Workbook

Sheet Lisez-moi
A1: Nouveaux kits SacAdo V2 : du préscolaire à la Terminale (proposition du 29 septembre 2026)
A3: Remplace le fichier « préscolaire et élémentaire » envoyé plus tôt. Rien n'est encore dans l'app : ce fichier sert à valider.
A4: 69 kits : 9 classes du préscolaire et de l'élémentaire, 4 du collège, 10 du lycée (Seconde L et S, Première et Terminale L1, L2, S1, S2).
A6: Tes consignes appliquées au préscolaire et à l'élémentaire
A7: • Craies blanches : vendues à l'unité à 25 F, 20 craies par kit (500 F au lieu de la boîte de 100 à 3 000 F). Produit à créer.
A8: • Matériel géométrique : une seule ligne du CE1 au CM2 au lieu de règle, équerre, rapporteur et compas. Au CP, la ligne est renommée.
A9: • Gourde violette (1287) à 2 500 F. Gourde ours à 3 100 F en Grande section Complet et Confort (déjà en place).
A10: • Lecture CI Kotti Kotti retiré du CI Confort. C'était le seul Kotti Kotti des kits.
A11: • Trousses Hello et gourdes : remarques de stock retirées.
A13: Collège et lycée : tes tableaux, rattachés au catalogue
A14: • Tes colonnes étaient dans l'ordre Essentiel, Confort, Complet : ici elles sont remises dans l'ordre de l'app (Essentiel < Complet < Confort).
A15: • Matériel géométrique = 1229, boîte d'instruments Marshal (1 800 F) dans toutes les gammes : elle a tout (compas compris) et coûte moins cher que les pièces séparées. Contenu à vérifier avec LPD.
... A35: À faire dans l'admin : les actions de ton côté.

Sheet Récap par kit
A1: Nouveaux kits, du préscolaire à la Terminale : prix et contrôle
A2: Prix = somme des lignes cochées de la section Principal (formules liées à l'onglet Contenu des kits). Les articles absents du catalogue ne comptent pas. Prix actuel = export de l'app du 29 septembre. Bénéfice = prix de vente moins prix d'achat, sur les seuls articles dont le prix d'achat est connu ; la dernière colonne dit combien du kit n'a pas de prix d'achat.
A4: Cycle | B4: Classe | C4: Gamme | D4: ID du kit dans l'app | E4: Prix actuel | F4: Nouveau prix | G4: Écart | H4: Articles cochés (nouveau) | I4: Articles cochés (actuel) | J4: Articles manquants au catalogue | K4: Ordre des gammes | L4: Coût d'achat (connu) | M4: Bénéfice (connu) | N4: Marge sur le connu | O4: Montant sans prix d'achat
A5: Préscolaire | B5: Petite section | C5: Essentiel | D5: 493 | E5: 1400 | F5: =SUMIFS('Contenu des kits'!$M$2:$M$1856,'Contenu des kits'!$B$2:$B$1856,B5,'Contenu des kits'!$C$2:$C$1856,C5) -> 12940 | G5: =IF(E5="","",F5-E5) -> 11540 | H5: =COUNTIFS('Contenu des kits'!$B$2:$B$1856,B5,'Contenu des kits'!$C$2:$C$1856,C5,'Contenu des kits'!$L$2:$L$1856,"Oui",'Contenu des kits'!$K$2:$K$1856,"Principal") -> 15 | I5: 2 | J5: =COUNTIFS('Contenu des kits'!$B$2:$B$1856,B5,'Contenu des kits'!$C$2:$C$1856,C5,'Contenu des kits'!$N$2:$N$1856,"MANQUE") -> 0 | K5: =IF(AND(F5<F6,F6<F7),"OK","À REVOIR") -> OK | L5: =SUMIFS('Contenu des kits'!$S$2:$S$1856,'Contenu des kits'!$B$2:$B$1856,B5,'Contenu des kits'!$C$2:$C$1856,C5) -> 5520 | M5: =SUMIFS('Contenu des kits'!$T$2:$T$1856,'Contenu des kits'!$B$2:$B$1856,B5,'Contenu des kits'!$C$2:$C$1856,C5) -> 2420 | N5: =IF(F5-O5=0,"",M5/(F5-O5)) -> 0.30478589 | O5: =SUMIFS('Contenu des kits'!$U$2:$U$1856,'Contenu des kits'!$B$2:$B$1856,B5,'Contenu des kits'!$C$2:$C$1856,C5) -> 5000
A6: Préscolaire | B6: Petite section | C6: Complet | D6: 494 | E6: 6150 | F6: =SUMIFS('Contenu des kits'!$M$2:$M$1856,'Contenu des kits'!$B$2:$B$1856,B6,'Contenu des kits'!$C$2:$C$1856,C6) -> 21500 | G6: =IF(E6="","",F6-E6) -> 15350 | H6: =COUNTIFS('Contenu des kits'!$B$2:$B$1856,B6,'Contenu des kits'!$C$2:$C$1856,C6,'Contenu des kits'!$L$2:$L$1856,"Oui",'Contenu des kits'!$K$2:$K$1856,"Principal") -> 19 | I6: 7 | J6: =COUNTIFS('Contenu des kits'!$B$2:$B$1856,B6,'Contenu des kits'!$C$2:$C$1856,C6,'Contenu des kits'!$N$2:$N$1856,"MANQUE") -> 3 | L6: =SUMIFS('Contenu des kits'!$S$2:$S$1856,'Contenu des kits'!$B$2:$B$1856,B6,'Contenu des kits'!$C$2:$C$1856,C6) -> 12090 | M6: =SUMIFS('Contenu des kits'!$T$2:$T$1856,'Contenu des kits'!$B$2:$B$1856,B6,'Contenu des kits'!$C$2:$C$1856,C6) -> 4460 | N6: =IF(F6-O6=0,"",M6/(F6-O6)) -> 0.2694864 | O6: =SUMIFS('Contenu des kits'!$U$2:$U$1856,'Contenu des kits'!$B$2:$B$1856,B6,'Contenu des kits'!$C$2:$C$1856,C6) -> 4950
A7: Préscolaire | B7: Petite section | C7: Confort | D7: 495 | E7: 15520 | F7: =SUMIFS('Contenu des kits'!$M$2:$M$1856,'Contenu des kits'!$B$2:$B$1856,B7,'Contenu des kits'!$C$2:$C$1856,C7) -> 38400 | G7: =IF(E7="","",F7-E7) -> 22880 | H7: =COUNTIFS('Contenu des kits'!$B$2:$B$1856,B7,'Contenu des kits'!$C$2:$C$1856,C7,'Contenu des kits'!$L$2:$L$1856,"Oui",'Contenu des kits'!$K$2:$K$1856,"Principal") -> 25 | I7: 10 | J7: =COUNTIFS('Contenu des kits'!$B$2:$B$1856,B7,'Contenu des kits'!$C$2:$C$1856,C7,'Contenu des kits'!$N$2:$N$1856,"MANQUE") -> 4 | L7: =SUMIFS('Contenu des kits'!$S$2:$S$1856,'Contenu des kits'!$B$2:$B$1856,B7,'Contenu des kits'!$C$2:$C$1856,C7) -> 21640 | M7: =SUMIFS('Contenu des kits'!$T$2:$T$1856,'Contenu des kits'!$B$2:$B$1856,B7,'Contenu des kits'!$C$2:$C$1856,C7) -> 6360 | N7: =IF(F7-O7=0,"",M7/(F7-O7)) -> 0.22714286 | O7: =SUMIFS('Contenu des kits'!$U$2:$U$1856,'Contenu des kits'!$B$2:$B$1856,B7,'Contenu des kits'!$C$2:$C$1856,C7) -> 10400
A9: Préscolaire | B9: Moyenne section | C9: Essentiel | D9: 496 | E9: 7800 | F9: =SUMIFS('Contenu des kits'!$M$2:$M$1856,'Contenu des kits'!$B$2:$B$1856,B9,'Contenu des kits'!$C$2:$C$1856,C9) -> 12490 | G9: =IF(E9="","",F9-E9) -> 4690 | H9: =COUNTIFS('Contenu des kits'!$B$2:$B$1856,B9,'Contenu des kits'!$C$2:$C$1856,C9,'Contenu des kits'!$L$2:$L$1856,"Oui",'Contenu des kits'!$K$2:$K$1856,"Principal") -> 15 | I9: 10 | J9: =COUNTIFS('Contenu des kits'!$B$2:$B$1856,B9,'Contenu des kits'!$C$2:$C$1856,C9,'Contenu des kits'!$N$2:$N$1856,"MANQUE") -> 0 | K9: =IF(AND(F9<F10,F10<F11),"OK","À REVOIR") -> OK | L9: =SUMIFS('Contenu des kits'!$S$2:$S$1856,'Contenu des kits'!$B$2:$B$1856,B9,'Contenu des kits'!$C$2:$C$1856,C9) -> 5870 | M9: =SUMIFS('Contenu des kits'!$T$2:$T$1856,'Contenu des kits'!$B$2:$B$1856,B9,'Contenu des kits'!$C$2:$C$1856,C9) -> 2520 | N9: =IF(F9-O9=0,"",M9/(F9-O9)) -> 0.30035757 | O9: =SUMIFS('Contenu des kits'!$U$2:$U$1856,'Contenu des kits'!$B$2:$B$1856,B9,'Contenu des kits'!$C$2:$C$1856,C9) -> 4100
A10: Préscolaire | B10: Moyenne section | C10: Complet | D10: 497 | E10: 13900 | F10: =SUMIFS('Contenu des kits'!$M$2:$M$1856,'Contenu des kits'!$B$2:$B$1856,B10,'Contenu des kits'!$C$2:$C$1856,C10) -> 19050 | G10: =IF(E10="","",F10-E10) -> 5150 | H10: =COUNTIFS('Contenu des kits'!$B$2:$B$1856,B10,'Contenu des kits'!$C$2:$C$1856,C10,'Contenu des kits'!$L$2:$L$1856,"Oui",'Contenu des kits'!$K$2:$K$1856,"Principal") -> 18 | I10: 15 | J10: =COUNTIFS('Contenu des kits'!$B$2:$B$1856,B10,'Contenu des kits'!$C$2:$C$1856,C10,'Contenu des kits'!$N$2:$N$1856,"MANQUE") -> 2 | L10: =SUMIFS('Contenu des kits'!$S$2:$S$1856,'Contenu des kits'!$B$2:$B$1856,B10,'Contenu des kits'!$C$2:$C$1856,C10) -> 10940 | M10: =SUMIFS('Contenu des kits'!$T$2:$T$1856,'Contenu des kits'!$B$2:$B$1856,B10,'Contenu des kits'!$C$2:$C$1856,C10) -> 4060 | N10: =IF(F10-O10=0,"",M10/(F10-O10)) -> 0.27066667 | O10: =SUMIFS('Contenu des kits'!$U$2:$U$1856,'Contenu des kits'!$B$2:$B$1856,B10,'Contenu des kits'!$C$2:$C$1856,C10) -> 4050
A11: Préscolaire | B11: Moyenne section | C11: Confort | D11: 498 | E11: 28470 | F11: =SUMIFS('Contenu des kits'!$M$2:$M$1856,'Contenu des kits'!$B$2:$B$1856,B11,'Contenu des kits'!$C$2:$C$1856,C11) -> 35450 | G11: =IF(E11="","",F11-E11) -> 6980 | H11: =COUNTIFS('Contenu des kits'!$B$2:$B$1856,B11,'Contenu des kits'!$C$2:$C$1856,C11,'Contenu des kits'!$L$2:$L$1856,"Oui",'Contenu des kits'!$K$2:$K$1856,"Principal") -> 23 | I11: 20 | J11: =COUNTIFS('Contenu des kits'!$B$2:$B$1856,B11,'Contenu des kits'!$C$2:$C$1856,C11,'Contenu des kits'!$N$2:$N$1856,"MANQUE") -> 4 | L11: =SUMIFS('Contenu des kits'!$S$2:$S$1856,'Contenu des kits'!$B$2:$B$1856,B11,'Contenu des kits'!$C$2:$C$1856,C11) -> 19500 | M11: =SUMIFS('Contenu des kits'!$T$2:$T$1856,'Contenu des kits'!$B$2:$B$1856,B11,'Contenu des kits'!$C$2:$C$1856,C11) -> 5650 | N11: =IF(F11-O11=0,"",M11/(F11-O11)) -> 0.22465209 | O11: =SUMIFS('Contenu des kits'!$U$2:$U$1856,'Contenu des kits'!$B$2:$B$1856,B11,'Contenu des kits'!$C$2:$C$1856,C11) -> 10300
A13: Préscolaire | B13: Grande section | C13: Essentiel | D13: 499 | E13: 8250 | F13: =SUMIFS('Contenu des kits'!$M$2:$M$1856,'Contenu des kits'!$B$2:$B$1856,B13,'Contenu des kits'!$C$2:$C$1856,C13) -> 12940 | G13: =IF(E13="","",F13-E13) -> 4690 | H13: =COUNTIFS('Contenu des kits'!$B$2:$B$1856,B13,'Contenu des kits'!$C$2:$C$1856,C13,'Contenu des kits'!$L$2:$L$1856,"Oui",'Contenu des kits'!$K$2:$K$1856,"Principal") -> 15 | I13: 10 | J13: =COUNTIFS('Contenu des kits'!$B$2:$B$1856,B13,'Contenu des kits'!$C$2:$C$1856,C13,'Contenu des kits'!$N$2:$N$1856,"MANQUE") -> 0 | K13: =IF(AND(F13<F14,F14<F15),"OK","À REVOIR") -> OK | L13: =SUMIFS('Contenu des kits'!$S$2:$S$1856,'Contenu des kits'!$B$2:$B$1856,B13,'Contenu des kits'!$C$2:$C$1856,C13) -> 6220 | M13: =SUMIFS('Contenu des kits'!$T$2:$T$1856,'Contenu des kits'!$B$2:$B$1856,B13,'Contenu des kits'!$C$2:$C$1856,C13) -> 2620 | N13: =IF(F13-O13=0,"",M13/(F13-O13)) -> 0.29638009 | O13: =SUMIFS('Contenu des kits'!$U$2:$U$1856,'Contenu des kits'!$B$2:$B$1856,B13,'Contenu des kits'!$C$2:$C$1856,C13) -> 4100
A14: Préscolaire | B14: Grande section | C14: Complet | D14: 500 | E14: 14350 | F14: =SUMIFS('Contenu des kits'!$M$2:$M$1856,'Contenu des kits'!$B$2:$B$1856,B14,'Contenu des kits'!$C$2:$C$1856,C14) -> 19500 | G14: =IF(E14="","",F14-E14) -> 5150 | H14: =COUNTIFS('Contenu des kits'!$B$2:$B$1856,B14,'Contenu des kits'!$C$2:$C$1856,C14,'Contenu des kits'!$L$2:$L$1856,"Oui",'Contenu des kits'!$K$2:$K$1856,"Principal") -> 18 | I14: 15 | J14: =COUNTIFS('Contenu des kits'!$B$2:$B$1856,B14,'Contenu des kits'!$C$2:$C$1856,C14,'Contenu des kits'!$N$2:$N$1856,"MANQUE") -> 2 | L14: =SUMIFS('Contenu des kits'!$S$2:$S$1856,'Contenu des kits'!$B$2:$B$1856,B14,'Contenu des kits'!$C$2:$C$1856,C14) -> 11290 | M14: =SUMIFS('Contenu des kits'!$T$2:$T$1856,'Contenu des kits'!$B$2:$B$1856,B14,'Contenu des kits'!$C$2:$C$1856,C14) -> 4160 | N14: =IF(F14-O14=0,"",M14/(F14-O14)) -> 0.26925566 | O14: =SUMIFS('Contenu des kits'!$U$2:$U$1856,'Contenu des kits'!$B$2:$B$1856,B14,'Contenu des kits'!$C$2:$C$1856,C14) -> 4050
A15: Préscolaire | B15: Grande section | C15: Confort | D15: 501 | E15: 28920 | F15: =SUMIFS('Contenu des kits'!$M$2:$M$1856,'Contenu des kits'!$B$2:$B$1856,B15,'Contenu des kits'!$C$2:$C$1856,C15) -> 36700 | G15: =IF(E15="","",F15-E15) -> 7780 | H15: =COUNTIFS('Contenu des kits'!$B$2:$B$1856,B15,'Contenu des kits'!$C$2:$C$1856,C15,'Contenu des kits'!$L$2:$L$1856,"Oui",'Contenu des kits'!$K$2:$K$1856,"Principal") -> 23 | I15: 20 | J15: =COUNTIFS('Contenu des kits'!$B$2:$B$1856,B15,'Contenu des kits'!$C$2:$C$1856,C15,'Contenu des kits'!$N$2:$N$1856,"MANQUE") -> 4 | L15: =SUMIFS('Contenu des kits'!$S$2:$S$1856,'Contenu des kits'!$B$2:$B$1856,B15,'Contenu des kits'!$C$2:$C$1856,C15) -> 19850 | M15: =SUMIFS('Contenu des kits'!$T$2:$T$1856,'Contenu des kits'!$B$2:$B$1856,B15,'Contenu des kits'!$C$2:$C$1856,C15) -> 5750 | N15: =IF(F15-O15=0,"",M15/(F15-O15)) -> 0.22460938 | O15: =SUMIFS('Contenu des kits'!$U$2:$U$1856,'Contenu des kits'!$B$2:$B$1856,B15,'Contenu des kits'!$C$2:$C$1856,C15) -> 11100
A17: Élémentaire | B17: CI | C17: Essentiel | D17: 1 | E17: 7750 | F17: =SUMIFS('Contenu des kits'!$M$2:$M$1856,'Contenu des kits'!$B$2:$B$1856,B17,'Contenu des kits'!$C$2:$C$1856,C17) -> 12420 | G17: =IF(E17="","",F17-E17) -> 4670 | H17: =COUNTIFS('Contenu des kits'!$B$2:$B$1856,B17,'Contenu des kits'!$C$2:$C$1856,C17,'Contenu des kits'!$L$2:$L$1856,"Oui",'Contenu des kits'!$K$2:$K$1856,"Principal") -> 17 | I17: 11 | J17: =COUNTIFS('Contenu des kits'!$B$2:$B$1856,B17,'Contenu des kits'!$C$2:$C$1856,C17,'Contenu des kits'!$N$2:$N$1856,"MANQUE") -> 0 | K17: =IF(AND(F17<F18,F18<F19),"OK","À REVOIR") -> OK | L17: =SUMIFS('Contenu des kits'!$S$2:$S$1856,'Contenu des kits'!$B$2:$B$1856,B17,'Contenu des kits'!$C$2:$C$1856,C17) -> 5700 | M17: =SUMIFS('Contenu des kits'!$T$2:$T$1856,'Contenu des kits'!$B$2:$B$1856,B17,'Contenu des kits'!$C$2:$C$1856,C17) -> 2570 | N17: =IF(F17-O17=0,"",M17/(F17-O17)) -> 0.31076179 | O17: =SUMIFS('Contenu des kits'!$U$2:$U$1856,'Contenu des kits'!$B$2:$B$1856,B17,'Contenu des kits'!$C$2:$C$1856,C17) -> 4150
A18: Élémentaire | B18: CI | C18: Complet | D18: 13 | E18: 25580 | F18: =SUMIFS('Contenu des kits'!$M$2:$M$1856,'Contenu des kits'!$B$2:$B$1856,B18,'Contenu des kits'!$C$2:$C$1856,C18) -> 27080 | G18: =IF(E18="","",F18-E18) -> 1500 | H18: =COUNTIFS('Contenu des kits'!$B$2:$B$1856,B18,'Contenu des kits'!$C$2:$C$1856,C18,'Contenu des kits'!$L$2:$L$1856,"Oui",'Contenu des kits'!$K$2:$K$1856,"Principal") -> 20 | I18: 18 | J18: =COUNTIFS('Contenu des kits'!$B$2:$B$1856,B18,'Contenu des kits'!$C$2:$C$1856,C18,'Contenu des kits'!$N$2:$N$1856,"MANQUE") -> 0 | L18: =SUMIFS('Contenu des kits'!$S$2:$S$1856,'Contenu des kits'!$B$2:$B$1856,B18,'Contenu des kits'!$C$2:$C$1856,C18) -> 16578 | M18: =SUMIFS('Contenu des kits'!$T$2:$T$1856,'Contenu des kits'!$B$2:$B$1856,B18,'Contenu des kits'!$C$2:$C$1856,C18) -> 6352 | N18: =IF(F18-O18=0,"",M18/(F18-O18)) -> 0.27701701 | O18: =SUMIFS('Contenu des kits'!$U$2:$U$1856,'Contenu des kits'!$B$2:$B$1856,B18,'Contenu des kits'!$C$2:$C$1856,C18) -> 4150
A19: Élémentaire | B19: CI | C19: Confort | D19: 7 | E19: 32360 | F19: =SUMIFS('Contenu des kits'!$M$2:$M$1856,'Contenu des kits'!$B$2:$B$1856,B19,'Contenu des kits'!$C$2:$C$1856,C19) -> 36520 | G19: =IF(E19="","",F19-E19) -> 4160 | H19: =COUNTIFS('Contenu des kits'!$B$2:$B$1856,B19,'Contenu des kits'!$C$2:$C$1856,C19,'Contenu des kits'!$L$2:$L$1856,"Oui",'Contenu des kits'!$K$2:$K$1856,"Principal") -> 23 | I19: 20 | J19: =COUNTIFS('Contenu des kits'!$B$2:$B$1856,B19,'Contenu des kits'!$C$2:$C$1856,C19,'Contenu des kits'!$N$2:$N$1856,"MANQUE") -> 0 | L19: =SUMIFS('Contenu des kits'!$S$2:$S$1856,'Contenu des kits'!$B$2:$B$1856,B19,'Contenu des kits'!$C$2:$C$1856,C19) -> 22968 | M19: =SUMIFS('Contenu des kits'!$T$2:$T$1856,'Contenu des kits'!$B$2:$B$1856,B19,'Contenu des kits'!$C$2:$C$1856,C19) -> 9402 | N19: =IF(F19-O19=0,"",M19/(F19-O19)) -> 0.29045412 | O19: =SUMIFS('Contenu des kits'!$U$2:$U$1856,'Contenu des kits'!$B$2:$B$1856,B19,'Contenu des kits'!$C$2:$C$1856,C19) -> 4150
A21: Élémentaire | B21: CP | C21: Essentiel | D21: 2 | E21: 8550 | F21: =SUMIFS('Contenu des kits'!$M$2:$M$1856,'Contenu des kits'!$B$2:$B$1856,B21,'Contenu des kits'!$C$2:$C$1856,C21) -> 15245 | G21: =IF(E21="","",F21-E21) -> 6695 | H21: =COUNTIFS('Contenu des kits'!$B$2:$B$1856,B21,'Contenu des kits'!$C$2:$C$1856,C21,'Contenu des kits'!$L$2:$L$1856,"Oui",'Contenu des kits'!$K$2:$K$1856,"Principal") -> 20 | I21: 12 | J21: =COUNTIFS('Contenu des kits'!$B$2:$B$1856,B21,'Contenu des kits'!$C$2:$C$1856,C21,'Contenu des kits'!$N$2:$N$1856,"MANQUE") -> 1 | K21: =IF(AND(F21<F22,F22<F23),"OK","À REVOIR") -> OK | L21: =SUMIFS('Contenu des kits'!$S$2:$S$1856,'Contenu des kits'!$B$2:$B$1856,B21,'Contenu des kits'!$C$2:$C$1856,C21) -> 7385 | M21: =SUMIFS('Contenu des kits'!$T$2:$T$1856,'Contenu des kits'!$B$2:$B$1856,B21,'Contenu des kits'!$C$2:$C$1856,C21) -> 3610 | N21: =IF(F21-O21=0,"",M21/(F21-O21)) -> 0.32833106 | O21: =SUMIFS('Contenu des kits'!$U$2:$U$1856,'Contenu des kits'!$B$2:$B$1856,B21,'Contenu des kits'!$C$2:$C$1856,C21) -> 4250
A22: Élémentaire | B22: CP | C22: Complet | D22: 14 | E22: 26380 | F22: =SUMIFS('Contenu des kits'!$M$2:$M$1856,'Contenu des kits'!$B$2:$B$1856,B22,'Contenu des kits'!$C$2:$C$1856,C22) -> 32445 | G22: =IF(E22="","",F22-E22) -> 6065 | H22: =COUNTIFS('Contenu des kits'!$B$2:$B$1856,B22,'Contenu des kits'!$C$2:$C$1856,C22,'Contenu des kits'!$L$2:$L$1856,"Oui",'Contenu des kits'!$K$2:$K$1856,"Principal") -> 24 | I22: 19 | J22: =COUNTIFS('Contenu des kits'!$B$2:$B$1856,B22,'Contenu des kits'!$C$2:$C$1856,C22,'Contenu des kits'!$N$2:$N$1856,"MANQUE") -> 1 | L22: =SUMIFS('Contenu des kits'!$S$2:$S$1856,'Contenu des kits'!$B$2:$B$1856,B22,'Contenu des kits'!$C$2:$C$1856,C22) -> 19463 | M22: =SUMIFS('Contenu des kits'!$T$2:$T$1856,'Contenu des kits'!$B$2:$B$1856,B22,'Contenu des kits'!$C$2:$C$1856,C22) -> 8532 | N22: =IF(F22-O22=0,"",M22/(F22-O22)) -> 0.30476871 | O22: =SUMIFS('Contenu des kits'!$U$2:$U$1856,'Contenu des kits'!$B$2:$B$1856,B22,'Contenu des kits'!$C$2:$C$1856,C22) -> 4450
A23: Élémentaire | B23: CP | C23: Confort | D23: 8 | E23: 33160 | F23: =SUMIFS('Contenu des kits'!$M$2:$M$1856,'Contenu des kits'!$B$2:$B$1856,B23,'Contenu des kits'!$C$2:$C$1856,C23) -> 50755 | G23: =IF(E23="","",F23-E23) -> 17595 | H23: =COUNTIFS('Contenu des kits'!$B$2:$B$1856,B23,'Contenu des kits'!$C$2:$C$1856,C23,'Contenu des kits'!$L$2:$L$1856,"Oui",'Contenu des kits'!$K$2:$K$1856,"Principal") -> 30 | I23: 21 | J23: =COUNTIFS('Contenu des kits'!$B$2:$B$1856,B23,'Contenu des kits'!$C$2:$C$1856,C23,'Contenu des kits'!$N$2:$N$1856,"MANQUE") -> 1 | L23: =SUMIFS('Contenu des kits'!$S$2:$S$1856,'Contenu des kits'!$B$2:$B$1856,B23,'Contenu des kits'!$C$2:$C$1856,C23) -> 31723 | M23: =SUMIFS('Contenu des kits'!$T$2:$T$1856,'Contenu des kits'!$B$2:$B$1856,B23,'Contenu des kits'!$C$2:$C$1856,C23) -> 14582 | N23: =IF(F23-O23=0,"",M23/(F23-O23)) -> 0.314912 | O23: =SUMIFS('Contenu des kits'!$U$2:$U$1856,'Contenu des kits'!$B$2:$B$1856,B23,'Contenu des kits'!$C$2:$C$1856,C23) -> 4450
A25: Élémentaire | B25: CE1 | C25: Essentiel | D25: 3 | E25: 10700 | F25: =SUMIFS('Contenu des kits'!$M$2:$M$1856,'Contenu des kits'!$B$2:$B$1856,B25,'Contenu des kits'!$C$2:$C$1856,C25) -> 15620 | G25: =IF(E25="","",F25-E25) -> 4920 | H25: =COUNTIFS('Contenu des kits'!$B$2:$B$1856,B25,'Contenu des kits'!$C$2:$C$1856,C25,'Contenu des kits'!$L$2:$L$1856,"Oui",'Contenu des kits'!$K$2:$K$1856,"Principal") -> 18 | I25: 15 | J25: =COUNTIFS('Contenu des kits'!$B$2:$B$1856,B25,'Contenu des kits'!$C$2:$C$1856,C25,'Contenu des kits'!$N$2:$N$1856,"MANQUE") -> 0 | K25: =IF(AND(F25<F26,F26<F27),"OK","À REVOIR") -> OK | L25: =SUMIFS('Contenu des kits'!$S$2:$S$1856,'Contenu des kits'!$B$2:$B$1856,B25,'Contenu des kits'!$C$2:$C$1856,C25) -> 8160 | M25: =SUMIFS('Contenu des kits'!$T$2:$T$1856,'Contenu des kits'!$B$2:$B$1856,B25,'Contenu des kits'!$C$2:$C$1856,C25) -> 2960 | N25: =IF(F25-O25=0,"",M25/(F25-O25)) -> 0.26618705 | O25: =SUMIFS('Contenu des kits'!$U$2:$U$1856,'Contenu des kits'!$B$2:$B$1856,B25,'Contenu des kits'!$C$2:$C$1856,C25) -> 4500
A26: Élémentaire | B26: CE1 | C26: Complet | D26: 15 | E26: 29650 | F26: =SUMIFS('Contenu des kits'!$M$2:$M$1856,'Contenu des kits'!$B$2:$B$1856,B26,'Contenu des kits'!$C$2:$C$1856,C26) -> 35250 | G26: =IF(E26="","",F26-E26) -> 5600 | H26: =COUNTIFS('Contenu des kits'!$B$2:$B$1856,B26,'Contenu des kits'!$C$2:$C$1856,C26,'Contenu des kits'!$L$2:$L$1856,"Oui",'Contenu des kits'!$K$2:$K$1856,"Principal") -> 22 | I26: 21 | J26: =COUNTIFS('Contenu des kits'!$B$2:$B$1856,B26,'Contenu des kits'!$C$2:$C$1856,C26,'Contenu des kits'!$N$2:$N$1856,"MANQUE") -> 0 | L26: =SUMIFS('Contenu des kits'!$S$2:$S$1856,'Contenu des kits'!$B$2:$B$1856,B26,'Contenu des kits'!$C$2:$C$1856,C26) -> 22178 | M26: =SUMIFS('Contenu des kits'!$T$2:$T$1856,'Contenu des kits'!$B$2:$B$1856,B26,'Contenu des kits'!$C$2:$C$1856,C26) -> 8722 | N26: =IF(F26-O26=0,"",M26/(F26-O26)) -> 0.28226537 | O26: =SUMIFS('Contenu des kits'!$U$2:$U$1856,'Contenu des kits'!$B$2:$B$1856,B26,'Contenu des kits'!$C$2:$C$1856,C26) -> 4350
A27: Élémentaire | B27: CE1 | C27: Confort | D27: 9 | E27: 36870 | F27: =SUMIFS('Contenu des kits'!$M$2:$M$1856,'Contenu des kits'!$B$2:$B$1856,B27,'Contenu des kits'!$C$2:$C$1856,C27) -> 44980 | G27: =IF(E27="","",F27-E27) -> 8110 | H27: =COUNTIFS('Contenu des kits'!$B$2:$B$1856,B27,'Contenu des kits'!$C$2:$C$1856,C27,'Contenu des kits'!$L$2:$L$1856,"Oui",'Contenu des kits'!$K$2:$K$1856,"Principal") -> 25 | I27: 23 | J27: =COUNTIFS('Contenu des kits'!$B$2:$B$1856,B27,'Contenu des kits'!$C$2:$C$1856,C27,'Contenu des kits'!$N$2:$N$1856,"MANQUE") -> 0 | L27: =SUMIFS('Contenu des kits'!$S$2:$S$1856,'Contenu des kits'!$B$2:$B$1856,B27,'Contenu des kits'!$C$2:$C$1856,C27) -> 28858 | M27: =SUMIFS('Contenu des kits'!$T$2:$T$1856,'Contenu des kits'!$B$2:$B$1856,B27,'Contenu des kits'!$C$2:$C$1856,C27) -> 11772 | N27: =IF(F27-O27=0,"",M27/(F27-O27)) -> 0.28973665 | O27: =SUMIFS('Contenu des kits'!$U$2:$U$1856,'Contenu des kits'!$B$2:$B$1856,B27,'Contenu des kits'!$C$2:$C$1856,C27) -> 4350
A29: Élémentaire | B29: CE2 | C29: Essentiel | D29: 4 | E29: 10700 | F29: =SUMIFS('Contenu des kits'!$M$2:$M$1856,'Contenu des kits'!$B$2:$B$1856,B29,'Contenu des kits'!$C$2:$C$1856,C29) -> 15620 | G29: =IF(E29="","",F29-E29) -> 4920 | H29: =COUNTIFS('Contenu des kits'!$B$2:$B$1856,B29,'Contenu des kits'!$C$2:$C$1856,C29,'Contenu des kits'!$L$2:$L$1856,"Oui",'Contenu des kits'!$K$2:$K$1856,"Principal") -> 18 | I29: 15 | J29: =COUNTIFS('Contenu des kits'!$B$2:$B$1856,B29,'Contenu des kits'!$C$2:$C$1856,C29,'Contenu des kits'!$N$2:$N$1856,"MANQUE") -> 0 | K29: =IF(AND(F29<F30,F30<F31),"OK","À REVOIR") -> OK | L29: =SUMIFS('Contenu des kits'!$S$2:$S$1856,'Contenu des kits'!$B$2:$B$1856,B29,'Contenu des kits'!$C$2:$C$1856,C29) -> 8160 | M29: =SUMIFS('Contenu des kits'!$T$2:$T$1856,'Contenu des kits'!$B$2:$B$1856,B29,'Contenu des kits'!$C$2:$C$1856,C29) -> 2960 | N29: =IF(F29-O29=0,"",M29/(F29-O29)) -> 0.26618705 | O29: =SUMIFS('Contenu des kits'!$U$2:$U$1856,'Contenu des kits'!$B$2:$B$1856,B29,'Contenu des kits'!$C$2:$C$1856,C29) -> 4500
A30: Élémentaire | B30: CE2 | C30: Complet | D30: 16 | E30: 29650 | F30: =SUMIFS('Contenu des kits'!$M$2:$M$1856,'Contenu des kits'!$B$2:$B$1856,B30,'Contenu des kits'!$C$2:$C$1856,C30) -> 35250 | G30: =IF(E30="","",F30-E30) -> 5600 | H30: =COUNTIFS('Contenu des kits'!$B$2:$B$1856,B30,'Contenu des kits'!$C$2:$C$1856,C30,'Contenu des kits'!$L$2:$L$1856,"Oui",'Contenu des kits'!$K$2:$K$1856,"Principal") -> 22 | I30: 21 | J30: =COUNTIFS('Contenu des kits'!$B$2:$B$1856,B30,'Contenu des kits'!$C$2:$C$1856,C30,'Contenu des kits'!$N$2:$N$1856,"MANQUE") -> 0 | L30: =SUMIFS('Contenu des kits'!$S$2:$S$1856,'Contenu des kits'!$B$2:$B$1856,B30,'Contenu des kits'!$C$2:$C$1856,C30) -> 22178 | M30: =SUMIFS('Contenu des kits'!$T$2:$T$1856,'Contenu des kits'!$B$2:$B$1856,B30,'Contenu des kits'!$C$2:$C$1856,C30) -> 8722 | N30: =IF(F30-O30=0,"",M30/(F30-O30)) -> 0.28226537 | O30: =SUMIFS('Contenu des kits'!$U$2:$U$1856,'Contenu des kits'!$B$2:$B$1856,B30,'Contenu des kits'!$C$2:$C$1856,C30) -> 4350
A31: Élémentaire | B31: CE2 | C31: Confort | D31: 10 | E31: 36870 | F31: =SUMIFS('Contenu des kits'!$M$2:$M$1856,'Contenu des kits'!$B$2:$B$1856,B31,'Contenu des kits'!$C$2:$C$1856,C31) -> 51990 | G31: =IF(E31="","",F31-E31) -> 15120 | H31: =COUNTIFS('Contenu des kits'!$B$2:$B$1856,B31,'Contenu des kits'!$C$2:$C$1856,C31,'Contenu des kits'!$L$2:$L$1856,"Oui",'Contenu des kits'!$K$2:$K$1856,"Principal") -> 27 | I31: 23 | J31: =COUNTIFS('Contenu des kits'!$B$2:$B$1856,B31,'Contenu des kits'!$C$2:$C$1856,C31,'Contenu des kits'!$N$2:$N$1856,"MANQUE") -> 0 | L31: =SUMIFS('Contenu des kits'!$S$2:$S$1856,'Contenu des kits'!$B$2:$B$1856,B31,'Contenu des kits'!$C$2:$C$1856,C31) -> 33868 | M31: =SUMIFS('Contenu des kits'!$T$2:$T$1856,'Contenu des kits'!$B$2:$B$1856,B31,'Contenu des kits'!$C$2:$C$1856,C31) -> 13772 | N31: =IF(F31-O31=0,"",M31/(F31-O31)) -> 0.2890848 | O31: =SUMIFS('Contenu des kits'!$U$2:$U$1856,'Contenu des kits'!$B$2:$B$1856,B31,'Contenu des kits'!$C$2:$C$1856,C31) -> 4350
A33: Élémentaire | B33: CM1 | C33: Essentiel | D33: 5 | E33: 12425 | F33: =SUMIFS('Contenu des kits'!$M$2:$M$1856,'Contenu des kits'!$B$2:$B$1856,B33,'Contenu des kits'!$C$2:$C$1856,C33) -> 17290 | G33: =IF(E33="","",F33-E33) -> 4865 | H33: =COUNTIFS('Contenu des kits'!$B$2:$B$1856,B33,'Contenu des kits'!$C$2:$C$1856,C33,'Contenu des kits'!$L$2:$L$1856,"Oui",'Contenu des kits'!$K$2:$K$1856,"Principal") -> 18 | I33: 17 | J33: =COUNTIFS('Contenu des kits'!$B$2:$B$1856,B33,'Contenu des kits'!$C$2:$C$1856,C33,'Contenu des kits'!$N$2:$N$1856,"MANQUE") -> 0 | K33: =IF(AND(F33<F34,F34<F35),"OK","À REVOIR") -> OK | L33: =SUMIFS('Contenu des kits'!$S$2:$S$1856,'Contenu des kits'!$B$2:$B$1856,B33,'Contenu des kits'!$C$2:$C$1856,C33) -> 9440 | M33: =SUMIFS('Contenu des kits'!$T$2:$T$1856,'Contenu des kits'!$B$2:$B$1856,B33,'Contenu des kits'!$C$2:$C$1856,C33) -> 3400 | N33: =IF(F33-O33=0,"",M33/(F33-O33)) -> 0.26479751 | O33: =SUMIFS('Contenu des kits'!$U$2:$U$1856,'Contenu des kits'!$B$2:$B$1856,B33,'Contenu des kits'!$C$2:$C$1856,C33) -> 4450
A34: Élémentaire | B34: CM1 | C34: Complet | D34: 17 | E34: 29975 | F34: =SUMIFS('Contenu des kits'!$M$2:$M$1856,'Contenu des kits'!$B$2:$B$1856,B34,'Contenu des kits'!$C$2:$C$1856,C34) -> 36850 | G34: =IF(E34="","",F34-E34) -> 6875 | H34: =COUNTIFS('Contenu des kits'!$B$2:$B$1856,B34,'Contenu des kits'!$C$2:$C$1856,C34,'Contenu des kits'!$L$2:$L$1856,"Oui",'Contenu des kits'!$K$2:$K$1856,"Principal") -> 22 | I34: 20 | J34: =COUNTIFS('Contenu des kits'!$B$2:$B$1856,B34,'Contenu des kits'!$C$2:$C$1856,C34,'Contenu des kits'!$N$2:$N$1856,"MANQUE") -> 0 | L34: =SUMIFS('Contenu des kits'!$S$2:$S$1856,'Contenu des kits'!$B$2:$B$1856,B34,'Contenu des kits'!$C$2:$C$1856,C34) -> 23168 | M34: =SUMIFS('Contenu des kits'!$T$2:$T$1856,'Contenu des kits'!$B$2:$B$1856,B34,'Contenu des kits'!$C$2:$C$1856,C34) -> 9182 | N34: =IF(F34-O34=0,"",M34/(F34-O34)) -> 0.28383308 | O34: =SUMIFS('Contenu des kits'!$U$2:$U$1856,'Contenu des kits'!$B$2:$B$1856,B34,'Contenu des kits'!$C$2:$C$1856,C34) -> 4500
A35: Élémentaire | B35: CM1 | C35: Confort | D35: 11 | E35: 37655 | F35: =SUMIFS('Contenu des kits'!$M$2:$M$1856,'Contenu des kits'!$B$2:$B$1856,B35,'Contenu des kits'!$C$2:$C$1856,C35) -> 51270 | G35: =IF(E35="","",F35-E35) -> 13615 | H35: =COUNTIFS('Contenu des kits'!$B$2:$B$1856,B35,'Contenu des kits'!$C$2:$C$1856,C35,'Contenu des kits'!$L$2:$L$1856,"Oui",'Contenu des kits'!$K$2:$K$1856,"Principal") -> 26 | I35: 22 | J35: =COUNTIFS('Contenu des kits'!$B$2:$B$1856,B35,'Contenu des kits'!$C$2:$C$1856,C35,'Contenu des kits'!$N$2:$N$1856,"MANQUE") -> 0 | L35: =SUMIFS('Contenu des kits'!$S$2:$S$1856,'Contenu des kits'!$B$2:$B$1856,B35,'Contenu des kits'!$C$2:$C$1856,C35) -> 33538 | M35: =SUMIFS('Contenu des kits'!$T$2:$T$1856,'Contenu des kits'!$B$2:$B$1856,B35,'Contenu des kits'!$C$2:$C$1856,C35) -> 13232 | N35: =IF(F35-O35=0,"",M35/(F35-O35)) -> 0.2829164 | O35: =SUMIFS('Contenu des kits'!$U$2:$U$1856,'Contenu des kits'!$B$2:$B$1856,B35,'Contenu des kits'!$C$2:$C$1856,C35) -> 4500
A37: Élémentaire | B37: CM2 | C37: Essentiel | D37: 6 | E37: 12425 | F37: =SUMIFS('Contenu des kits'!$M$2:$M$1856,'Contenu des kits'!$B$2:$B$1856,B37,'Contenu des kits'!$C$2:$C$1856,C37) -> 17290 | G37: =IF(E37="","",F37-E37) -> 4865 | H37: =COUNTIFS('Contenu des kits'!$B$2:$B$1856,B37,'Contenu des kits'!$C$2:$C$1856,C37,'Contenu des kits'!$L$2:$L$1856,"Oui",'Contenu des kits'!$K$2:$K$1856,"Principal") -> 18 | I37: 17 | J37: =COUNTIFS('Contenu des kits'!$B$2:$B$1856,B37,'Contenu des kits'!$C$2:$C$1856,C37,'Contenu des kits'!$N$2:$N$1856,"MANQUE") -> 0 | K37: =IF(AND(F37<F38,F38<F39),"OK","À REVOIR") -> OK | L37: =SUMIFS('Contenu des kits'!$S$2:$S$1856,'Contenu des kits'!$B$2:$B$1856,B37,'Contenu des kits'!$C$2:$C$1856,C37) -> 9440 | M37: =SUMIFS('Contenu des kits'!$T$2:$T$1856,'Contenu des kits'!$B$2:$B$1856,B37,'Contenu des kits'!$C$2:$C$1856,C37) -> 3400 | N37: =IF(F37-O37=0,"",M37/(F37-O37)) -> 0.26479751 | O37: =SUMIFS('Contenu des kits'!$U$2:$U$1856,'Contenu des kits'!$B$2:$B$1856,B37,'Contenu des kits'!$C$2:$C$1856,C37) -> 4450
A38: Élémentaire | B38: CM2 | C38: Complet | D38: 18 | E38: 29975 | F38: =SUMIFS('Contenu des kits'!$M$2:$M$1856,'Contenu des kits'!$B$2:$B$1856,B38,'Contenu des kits'!$C$2:$C$1856,C38) -> 41500 | G38: =IF(E38="","",F38-E38) -> 11525 | H38: =COUNTIFS('Contenu des kits'!$B$2:$B$1856,B38,'Contenu des kits'!$C$2:$C$1856,C38,'Contenu des kits'!$L$2:$L$1856,"Oui",'Contenu des kits'!$K$2:$K$1856,"Principal") -> 23 | I38: 20 | J38: =COUNTIFS('Contenu des kits'!$B$2:$B$1856,B38,'Contenu des kits'!$C$2:$C$1856,C38,'Contenu des kits'!$N$2:$N$1856,"MANQUE") -> 0 | L38: =SUMIFS('Contenu des kits'!$S$2:$S$1856,'Contenu des kits'!$B$2:$B$1856,B38,'Contenu des kits'!$C$2:$C$1856,C38) -> 26818 | M38: =SUMIFS('Contenu des kits'!$T$2:$T$1856,'Contenu des kits'!$B$2:$B$1856,B38,'Contenu des kits'!$C$2:$C$1856,C38) -> 10182 | N38: =IF(F38-O38=0,"",M38/(F38-O38)) -> 0.27518919 | O38: =SUMIFS('Contenu des kits'!$U$2:$U$1856,'Contenu des kits'!$B$2:$B$1856,B38,'Contenu des kits'!$C$2:$C$1856,C38) -> 4500
A39: Élémentaire | B39: CM2 | C39: Confort | D39: 12 | E39: 40325 | F39: =SUMIFS('Contenu des kits'!$M$2:$M$1856,'Contenu des kits'!$B$2:$B$1856,B39,'Contenu des kits'!$C$2:$C$1856,C39) -> 59160 | G39: =IF(E39="","",F39-E39) -> 18835 | H39: =COUNTIFS('Contenu des kits'!$B$2:$B$1856,B39,'Contenu des kits'!$C$2:$C$1856,C39,'Contenu des kits'!$L$2:$L$1856,"Oui",'Contenu des kits'!$K$2:$K$1856,"Principal") -> 28 | I39: 22 | J39: =COUNTIFS('Contenu des kits'!$B$2:$B$1856,B39,'Contenu des kits'!$C$2:$C$1856,C39,'Contenu des kits'!$N$2:$N$1856,"MANQUE") -> 0 | L39: =SUMIFS('Contenu des kits'!$S$2:$S$1856,'Contenu des kits'!$B$2:$B$1856,B39,'Contenu des kits'!$C$2:$C$1856,C39) -> 39428 | M39: =SUMIFS('Contenu des kits'!$T$2:$T$1856,'Contenu des kits'!$B$2:$B$1856,B39,'Contenu des kits'!$C$2:$C$1856,C39) -> 15232 | N39: =IF(F39-O39=0,"",M39/(F39-O39)) -> 0.27866813 | O39: =SUMIFS('Contenu des kits'!$U$2:$U$1856,'Contenu des kits'!$B$2:$B$1856,B39,'Contenu des kits'!$C$2:$C$1856,C39) -> 4500
A41: Collège | B41: 6e | C41: Essentiel | D41: 37 | E41: 12550 | F41: =SUMIFS('Contenu des kits'!$M$2:$M$1856,'Contenu des kits'!$B$2:$B$1856,B41,'Contenu des kits'!$C$2:$C$1856,C41) -> 15370 | G41: =IF(E41="","",F41-E41) -> 2820 | H41: =COUNTIFS('Contenu des kits'!$B$2:$B$1856,B41,'Contenu des kits'!$C$2:$C$1856,C41,'Contenu des kits'!$L$2:$L$1856,"Oui",'Contenu des kits'!$K$2:$K$1856,"Principal") -> 15 | I41: 13 | J41: =COUNTIFS('Contenu des kits'!$B$2:$B$1856,B41,'Contenu des kits'!$C$2:$C$1856,C41,'Contenu des kits'!$N$2:$N$1856,"MANQUE") -> 3 | K41: =IF(AND(F41<F42,F42<F43),"OK","À REVOIR") -> OK | L41: =SUMIFS('Contenu des kits'!$S$2:$S$1856,'Contenu des kits'!$B$2:$B$1856,B41,'Contenu des kits'!$C$2:$C$1856,C41) -> 5870 | M41: =SUMIFS('Contenu des kits'!$T$2:$T$1856,'Contenu des kits'!$B$2:$B$1856,B41,'Contenu des kits'!$C$2:$C$1856,C41) -> 3100 | N41: =IF(F41-O41=0,"",M41/(F41-O41)) -> 0.34559643 | O41: =SUMIFS('Contenu des kits'!$U$2:$U$1856,'Contenu des kits'!$B$2:$B$1856,B41,'Contenu des kits'!$C$2:$C$1856,C41) -> 6400
A42: Collège | B42: 6e | C42: Complet | D42: 38 | E42: 32950 | F42: =SUMIFS('Contenu des kits'!$M$2:$M$1856,'Contenu des kits'!$B$2:$B$1856,B42,'Contenu des kits'!$C$2:$C$1856,C42) -> 55670 | G42: =IF(E42="","",F42-E42) -> 22720 | H42: =COUNTIFS('Contenu des kits'!$B$2:$B$1856,B42,'Contenu des kits'!$C$2:$C$1856,C42,'Contenu des kits'!$L$2:$L$1856,"Oui",'Contenu des kits'!$K$2:$K$1856,"Principal") -> 28 | I42: 19 | J42: =COUNTIFS('Contenu des kits'!$B$2:$B$1856,B42,'Contenu des kits'!$C$2:$C$1856,C42,'Contenu des kits'!$N$2:$N$1856,"MANQUE") -> 3 | L42: =SUMIFS('Contenu des kits'!$S$2:$S$1856,'Contenu des kits'!$B$2:$B$1856,B42,'Contenu des kits'!$C$2:$C$1856,C42) -> 35580 | M42: =SUMIFS('Contenu des kits'!$T$2:$T$1856,'Contenu des kits'!$B$2:$B$1856,B42,'Contenu des kits'!$C$2:$C$1856,C42) -> 11690 | N42: =IF(F42-O42=0,"",M42/(F42-O42)) -> 0.24730273 | O42: =SUMIFS('Contenu des kits'!$U$2:$U$1856,'Contenu des kits'!$B$2:$B$1856,B42,'Contenu des kits'!$C$2:$C$1856,C42) -> 8400
A43: Collège | B43: 6e | C43: Confort | D43: 39 | E43: 59980 | F43: =SUMIFS('Contenu des kits'!$M$2:$M$1856,'Contenu des kits'!$B$2:$B$1856,B43,'Contenu des kits'!$C$2:$C$1856,C43) -> 63530 | G43: =IF(E43="","",F43-E43) -> 3550 | H43: =COUNTIFS('Contenu des kits'!$B$2:$B$1856,B43,'Contenu des kits'!$C$2:$C$1856,C43,'Contenu des kits'!$L$2:$L$1856,"Oui",'Contenu des kits'!$K$2:$K$1856,"Principal") -> 30 | I43: 26 | J43: =COUNTIFS('Contenu des kits'!$B$2:$B$1856,B43,'Contenu des kits'!$C$2:$C$1856,C43,'Contenu des kits'!$N$2:$N$1856,"MANQUE") -> 4 | L43: =SUMIFS('Contenu des kits'!$S$2:$S$1856,'Contenu des kits'!$B$2:$B$1856,B43,'Contenu des kits'!$C$2:$C$1856,C43) -> 41240 | M43: =SUMIFS('Contenu des kits'!$T$2:$T$1856,'Contenu des kits'!$B$2:$B$1856,B43,'Contenu des kits'!$C$2:$C$1856,C43) -> 13890 | N43: =IF(F43-O43=0,"",M43/(F43-O43)) -> 0.25194994 | O43: =SUMIFS('Contenu des kits'!$U$2:$U$1856,'Contenu des kits'!$B$2:$B$1856,B43,'Contenu des kits'!$C$2:$C$1856,C43) -> 8400
A45: Collège | B45: 5e | C45: Essentiel | D45: 40 | E45: 12550 | F45: =SUMIFS('Contenu des kits'!$M$2:$M$1856,'Contenu des kits'!$B$2:$B$1856,B45,'Contenu des kits'!$C$2:$C$1856,C45) -> 16170 | G45: =IF(E45="","",F45-E45) -> 3620 | H45: =COUNTIFS('Contenu des kits'!$B$2:$B$1856,B45,'Contenu des kits'!$C$2:$C$1856,C45,'Contenu des kits'!$L$2:$L$1856,"Oui",'Contenu des kits'!$K$2:$K$1856,"Principal") -> 16 | I45: 13 | J45: =COUNTIFS('Contenu des kits'!$B$2:$B$1856,B45,'Contenu des kits'!$C$2:$C$1856,C45,'Contenu des kits'!$N$2:$N$1856,"MANQUE") -> 1 | K45: =IF(AND(F45<F46,F46<F47),"OK","À REVOIR") -> OK | L45: =SUMIFS('Contenu des kits'!$S$2:$S$1856,'Contenu des kits'!$B$2:$B$1856,B45,'Contenu des kits'!$C$2:$C$1856,C45) -> 5470 | M45: =SUMIFS('Contenu des kits'!$T$2:$T$1856,'Contenu des kits'!$B$2:$B$1856,B45,'Contenu des kits'!$C$2:$C$1856,C45) -> 3000 | N45: =IF(F45-O45=0,"",M45/(F45-O45)) -> 0.35419126 | O45: =SUMIFS('Contenu des kits'!$U$2:$U$1856,'Contenu des kits'!$B$2:$B$1856,B45,'Contenu des kits'!$C$2:$C$1856,C45) -> 7700
A46: Collège | B46: 5e | C46: Complet | D46: 41 | E46: 29050 | F46: =SUMIFS('Contenu des kits'!$M$2:$M$1856,'Contenu des kits'!$B$2:$B$1856,B46,'Contenu des kits'!$C$2:$C$1856,C46) -> 65430 | G46: =IF(E46="","",F46-E46) -> 36380 | H46: =COUNTIFS('Contenu des kits'!$B$2:$B$1856,B46,'Contenu des kits'!$C$2:$C$1856,C46,'Contenu des kits'!$L$2:$L$1856,"Oui",'Contenu des kits'!$K$2:$K$1856,"Principal") -> 31 | I46: 18 | J46: =COUNTIFS('Contenu des kits'!$B$2:$B$1856,B46,'Contenu des kits'!$C$2:$C$1856,C46,'Contenu des kits'!$N$2:$N$1856,"MANQUE") -> 1 | L46: =SUMIFS('Contenu des kits'!$S$2:$S$1856,'Contenu des kits'!$B$2:$B$1856,B46,'Contenu des kits'!$C$2:$C$1856,C46) -> 43340 | M46: =SUMIFS('Contenu des kits'!$T$2:$T$1856,'Contenu des kits'!$B$2:$B$1856,B46,'Contenu des kits'!$C$2:$C$1856,C46) -> 14190 | N46: =IF(F46-O46=0,"",M46/(F46-O46)) -> 0.24665392 | O46: =SUMIFS('Contenu des kits'!$U$2:$U$1856,'Contenu des kits'!$B$2:$B$1856,B46,'Contenu des kits'!$C$2:$C$1856,C46) -> 7900
A47: Collège | B47: 5e | C47: Confort | D47: 42 | E47: 60080 | F47: =SUMIFS('Contenu des kits'!$M$2:$M$1856,'Contenu des kits'!$B$2:$B$1856,B47,'Contenu des kits'!$C$2:$C$1856,C47) -> 80290 | G47: =IF(E47="","",F47-E47) -> 20210 | H47: =COUNTIFS('Contenu des kits'!$B$2:$B$1856,B47,'Contenu des kits'!$C$2:$C$1856,C47,'Contenu des kits'!$L$2:$L$1856,"Oui",'Contenu des kits'!$K$2:$K$1856,"Principal") -> 35 | I47: 26 | J47: =COUNTIFS('Contenu des kits'!$B$2:$B$1856,B47,'Contenu des kits'!$C$2:$C$1856,C47,'Contenu des kits'!$N$2:$N$1856,"MANQUE") -> 2 | L47: =SUMIFS('Contenu des kits'!$S$2:$S$1856,'Contenu des kits'!$B$2:$B$1856,B47,'Contenu des kits'!$C$2:$C$1856,C47) -> 54000 | M47: =SUMIFS('Contenu des kits'!$T$2:$T$1856,'Contenu des kits'!$B$2:$B$1856,B47,'Contenu des kits'!$C$2:$C$1856,C47) -> 18390 | N47: =IF(F47-O47=0,"",M47/(F47-O47)) -> 0.25404061 | O47: =SUMIFS('Contenu des kits'!$U$2:$U$1856,'Contenu des kits'!$B$2:$B$1856,B47,'Contenu des kits'!$C$2:$C$1856,C47) -> 7900
A49: Collège | B49: 4e | C49: Essentiel | D49: 43 | E49: 13000 | F49: =SUMIFS('Contenu des kits'!$M$2:$M$1856,'Contenu des kits'!$B$2:$B$1856,B49,'Contenu des kits'!$C$2:$C$1856,C49) -> 16720 | G49: =IF(E49="","",F49-E49) -> 3720 | H49: =COUNTIFS('Contenu des kits'!$B$2:$B$1856,B49,'Contenu des kits'!$C$2:$C$1856,C49,'Contenu des kits'!$L$2:$L$1856,"Oui",'Contenu des kits'!$K$2:$K$1856,"Principal") -> 16 | I49: 13 | J49: =COUNTIFS('Contenu des kits'!$B$2:$B$1856,B49,'Contenu des kits'!$C$2:$C$1856,C49,'Contenu des kits'!$N$2:$N$1856,"MANQUE") -> 1 | K49: =IF(AND(F49<F50,F50<F51),"OK","À REVOIR") -> OK | L49: =SUMIFS('Contenu des kits'!$S$2:$S$1856,'Contenu des kits'!$B$2:$B$1856,B49,'Contenu des kits'!$C$2:$C$1856,C49) -> 7020 | M49: =SUMIFS('Contenu des kits'!$T$2:$T$1856,'Contenu des kits'!$B$2:$B$1856,B49,'Contenu des kits'!$C$2:$C$1856,C49) -> 3400 | N49: =IF(F49-O49=0,"",M49/(F49-O49)) -> 0.32629559 | O49: =SUMIFS('Contenu des kits'!$U$2:$U$1856,'Contenu des kits'!$B$2:$B$1856,B49,'Contenu des kits'!$C$2:$C$1856,C49) -> 6300
A50: Collège | B50: 4e | C50: Complet | D50: 44 | E50: 37500 | F50: =SUMIFS('Contenu des kits'!$M$2:$M$1856,'Contenu des kits'!$B$2:$B$1856,B50,'Contenu des kits'!$C$2:$C$1856,C50) -> 74730 | G50: =IF(E50="","",F50-E50) -> 37230 | H50: =COUNTIFS('Contenu des kits'!$B$2:$B$1856,B50,'Contenu des kits'!$C$2:$C$1856,C50,'Contenu des kits'!$L$2:$L$1856,"Oui",'Contenu des kits'!$K$2:$K$1856,"Principal") -> 33 | I50: 19 | J50: =COUNTIFS('Contenu des kits'!$B$2:$B$1856,B50,'Contenu des kits'!$C$2:$C$1856,C50,'Contenu des kits'!$N$2:$N$1856,"MANQUE") -> 2 | L50: =SUMIFS('Contenu des kits'!$S$2:$S$1856,'Contenu des kits'!$B$2:$B$1856,B50,'Contenu des kits'!$C$2:$C$1856,C50) -> 51040 | M50: =SUMIFS('Contenu des kits'!$T$2:$T$1856,'Contenu des kits'!$B$2:$B$1856,B50,'Contenu des kits'!$C$2:$C$1856,C50) -> 16290 | N50: =IF(F50-O50=0,"",M50/(F50-O50)) -> 0.24194267 | O50: =SUMIFS('Contenu des kits'!$U$2:$U$1856,'Contenu des kits'!$B$2:$B$1856,B50,'Contenu des kits'!$C$2:$C$1856,C50) -> 7400
A51: Collège | B51: 4e | C51: Confort | D51: 45 | E51: 75520 | F51: =SUMIFS('Contenu des kits'!$M$2:$M$1856,'Contenu des kits'!$B$2:$B$1856,B51,'Contenu des kits'!$C$2:$C$1856,C51) -> 89620 | G51: =IF(E51="","",F51-E51) -> 14100 | H51: =COUNTIFS('Contenu des kits'!$B$2:$B$1856,B51,'Contenu des kits'!$C$2:$C$1856,C51,'Contenu des kits'!$L$2:$L$1856,"Oui",'Contenu des kits'!$K$2:$K$1856,"Principal") -> 37 | I51: 29 | J51: =COUNTIFS('Contenu des kits'!$B$2:$B$1856,B51,'Contenu des kits'!$C$2:$C$1856,C51,'Contenu des kits'!$N$2:$N$1856,"MANQUE") -> 4 | L51: =SUMIFS('Contenu des kits'!$S$2:$S$1856,'Contenu des kits'!$B$2:$B$1856,B51,'Contenu des kits'!$C$2:$C$1856,C51) -> 61730 | M51: =SUMIFS('Contenu des kits'!$T$2:$T$1856,'Contenu des kits'!$B$2:$B$1856,B51,'Contenu des kits'!$C$2:$C$1856,C51) -> 20490 | N51: =IF(F51-O51=0,"",M51/(F51-O51)) -> 0.24920944 | O51: =SUMIFS('Contenu des kits'!$U$2:$U$1856,'Contenu des kits'!$B$2:$B$1856,B51,'Contenu des kits'!$C$2:$C$1856,C51) -> 7400
A53: Collège | B53: 3e | C53: Essentiel | D53: 46 | E53: 13000 | F53: =SUMIFS('Contenu des kits'!$M$2:$M$1856,'Contenu des kits'!$B$2:$B$1856,B53,'Contenu des kits'!$C$2:$C$1856,C53) -> 17570 | G53: =IF(E53="","",F53-E53) -> 4570 | H53: =COUNTIFS('Contenu des kits'!$B$2:$B$1856,B53,'Contenu des kits'!$C$2:$C$1856,C53,'Contenu des kits'!$L$2:$L$1856,"Oui",'Contenu des kits'!$K$2:$K$1856,"Principal") -> 16 | I53: 13 | J53: =COUNTIFS('Contenu des kits'!$B$2:$B$1856,B53,'Contenu des kits'!$C$2:$C$1856,C53,'Contenu des kits'!$N$2:$N$1856,"MANQUE") -> 2 | K53: =IF(AND(F53<F54,F54<F55),"OK","À REVOIR") -> OK | L53: =SUMIFS('Contenu des kits'!$S$2:$S$1856,'Contenu des kits'!$B$2:$B$1856,B53,'Contenu des kits'!$C$2:$C$1856,C53) -> 7070 | M53: =SUMIFS('Contenu des kits'!$T$2:$T$1856,'Contenu des kits'!$B$2:$B$1856,B53,'Contenu des kits'!$C$2:$C$1856,C53) -> 3400 | N53: =IF(F53-O53=0,"",M53/(F53-O53)) -> 0.32473734 | O53: =SUMIFS('Contenu des kits'!$U$2:$U$1856,'Contenu des kits'!$B$2:$B$1856,B53,'Contenu des kits'!$C$2:$C$1856,C53) -> 7100
...

Sheet Par classe
A1: Composition par classe (quantités par gamme)
A2: « — » = pas dans la gamme. Rouge = pas au catalogue, jaune = à confirmer, bleu = remplacement, violet = produit à créer. (L) = livre proposé mais décoché en Essentiel ; (opt) = option décochée.
A4: PETITE SECTION
A5: Fourniture | B5: Essentiel | C5: Complet | D5: Confort | E5: Produit Essentiel | F5: Produit Complet | G5: Produit Confort | H5: Statut
A6: Cahier de travaux pratiques 100 pages | B6: 1 | C6: 1 | D6: 1 | E6: 1728 · Cahier de travaux pratiques MyFriend 100 pages · 900 F | F6: 1728 · Cahier de travaux pratiques MyFriend 100 pages · 900 F | G6: 1728 · Cahier de travaux pratiques MyFriend 100 pages · 900 F
A7: Cahier de travaux pratiques 200 pages | B7: 1 | C7: 1 | D7: 1 | E7: 1729 · Cahier de travaux pratiques MyFriend 200 pages · 1 300 F | F7: 1729 · Cahier de travaux pratiques MyFriend 200 pages · 1 300 F | G7: 1729 · Cahier de travaux pratiques MyFriend 200 pages · 1 300 F
A8: Cahier de dessin | B8: 1 | C8: 1 | D8: 1 | E8: 1572 · Cahier de dessin L'écolier 32 pages · 250 F | F8: 1286 · Cahier de dessin TPG · 550 F | G8: 1286 · Cahier de dessin TPG · 550 F
A9: Ardoise blanche avec feutre | B9: 1 | C9: 1 | D9: 1 | E9: 33 · Ardoise blanche + feutre effaçable · 1 200 F | F9: 33 · Ardoise blanche + feutre effaçable · 1 200 F | G9: 33 · Ardoise blanche + feutre effaçable · 1 200 F
A10: Feutres pour ardoise | B10: 2 | C10: 2 | D10: 2 | E10: 1698 · Marqueur tableau blanc BEIYUE B-105 · 400 F | F10: 1698 · Marqueur tableau blanc BEIYUE B-105 · 400 F | G10: 1698 · Marqueur tableau blanc BEIYUE B-105 · 400 F
A11: Effaceur d'ardoise | B11: 1 | C11: 1 | D11: 1 | E11: 1244 · Brosse tableau blanc magnetique RX T-29 · 400 F | F11: 1244 · Brosse tableau blanc magnetique RX T-29 · 400 F | G11: 1244 · Brosse tableau blanc magnetique RX T-29 · 400 F
A12: Crayon à papier HB | B12: 2 | C12: 2 | D12: 4 | E12: 1571 · Crayon papier couleur du Senegal - a l unite · 75 F | F12: 1571 · Crayon papier couleur du Senegal - a l unite · 75 F | G12: 1571 · Crayon papier couleur du Senegal - a l unite · 75 F
A13: Gomme | B13: 1 | C13: 1 | D13: 1 | E13: 9 · Gomme blanche · 150 F | F13: 1181 · Gomme Staedtler Mars Plastic · 250 F | G13: 1181 · Gomme Staedtler Mars Plastic · 250 F
A14: Taille-crayon avec réservoir | B14: 1 | C14: 1 | D14: 1 | E14: 1587 · Tailla Crayon 1 Trou + Réservoir Clean – MAPED · 500 F | F14: 1587 · Tailla Crayon 1 Trou + Réservoir Clean – MAPED · 500 F | G14: 1587 · Tailla Crayon 1 Trou + Réservoir Clean – MAPED · 500 F
A15: Crayons de couleur | B15: 1 | C15: 1 | D15: 1 | E15: 1589 · Crayon Couleur BTE X12 – MAPED · 900 F | F15: 1589 · Crayon Couleur BTE X12 – MAPED · 900 F | G15: 1594 · Crayons de Couleur Boite de 24 Nightfall – MAPED · 1 600 F
A16: Bâtons de colle | B16: 2 | C16: 2 | D16: 4 | E16: 1173 · Baton de colle Dolphin Stick Glue · 570 F | F16: 1604 · Bâton de colle 20 g – GIOTTO · 700 F | G16: 1604 · Bâton de colle 20 g – GIOTTO · 700 F
A17: Ciseaux à bouts ronds | B17: 1 | C17: 1 | D17: 1 | E17: 1250 · Ciseaux scolaires bouts ronds · 250 F | F17: 1586 · Ciseaux 13cm Security Stop – MAPED · 900 F | G17: 1586 · Ciseaux 13cm Security Stop – MAPED · 900 F
... A20: Gourde | B20: 1 | C20: 1 | D20: 1 | E20: 1287 · Gourde Drink violette · 2 500 F | F20: 1193 · Gourde enfant motif ours Naughty Bear · 3 100 F | G20: 1193 · Gourde enfant motif ours Naughty Bear · 3 100 F
A21: Cartable | B21: 1 (opt) | C21: 1 (opt) | D21: 1 | E21: 1252 · Cartable Kam Rad Cute Capybaras · 6 500 F | F21: 1252 · Cartable Kam Rad Cute Capybaras · 6 500 F | G21: 1252 · Cartable Kam Rad Cute Capybaras · 6 500 F
A22: Feutres de couleur | B22: — | C22: 1 | D22: 2 | F22: 1204 · Feutres Giotto Turbo Color 12 couleurs · 1 300 F | G22: 1204 · Feutres Giotto Turbo Color 12 couleurs · 1 300 F
A23: Pâte à modeler | B23: — | C23: 1 | D23: 1 | F23: pas au catalogue | G23: pas au catalogue | H23: MANQUE
A24: Tablier de peinture | B24: — | C24: 1 | D24: 1 | F24: pas au catalogue | G24: pas au catalogue | H24: MANQUE
A25: Gommettes | B25: — | C25: 1 | D25: 1 | F25: pas au catalogue | G25: pas au catalogue | H25: MANQUE
A26: Règle 20 cm | B26: — | C26: 1 | D26: 1 | F26: 1183 · Regle plastique transparente 20 cm · 100 F | G26: 1183 · Regle plastique transparente 20 cm · 100 F
A27: Mon cahier de lecture, Petite section | B27: — | C27: 1 | D27: 1 | F27: 1231 · Mon cahier de lecture - Petite Section · 3 250 F | G27: 1231 · Mon cahier de lecture - Petite Section · 3 250 F
A28: Deuxième trousse Hello | B28: — | C28: 1 | D28: 1 | F28: 1708 · Trousse Hello pingouin menthe · 2 000 F | G28: 1708 · Trousse Hello pingouin menthe · 2 000 F
A29: Craies de cire | B29: — | C29: — | D29: 1 | G29: 1230 · Craies grasses Giotto Cera 24 · 1 300 F
A30: Bloc de dessin blanc A4 | B30: — | C30: — | D30: 1 | G30: 31 · Bloc de dessin A4 (50 feuilles) · 1 500 F | H30: SUBSTITUT
A31: Papier Canson couleur | B31: — | C31: — | D31: 1 | G31: pas au catalogue | H31: MANQUE
A32: Peinture gouache | B32: — | C32: — | D32: 1 | G32: 29 · Set peinture gouache (12 couleurs) · 2 800 F
A33: Pinceaux | B33: — | C33: — | D33: 1 | G33: 30 · Pinceaux assortis (lot de 5) · 1 000 F
A34: Éponge pour la peinture | B34: — | C34: — | D34: 1 | G34: 1202 · Boîte à éponge · 250 F
A35: Prix du kit | B35: ='Récap par kit'!F5 -> 12940 | C35: ='Récap par kit'!F6 -> 21500 | D35: ='Récap par kit'!F7 -> 38400
A37: MOYENNE SECTION
A38: Fourniture | B38: Essentiel | C38: Complet | D38: Confort | E38: Produit Essentiel | F38: Produit Complet | G38: Produit Confort | H38: Statut
A39: Cahier 96 pages petit format | B39: 1 | C39: 1 | D39: 1 | E39: 1618 · Cahier 96 pages petit format – 56g – seyès calligraphe · 450 F | F39: 1618 · Cahier 96 pages petit format – 56g – seyès calligraphe · 450 F | G39: 1618 · Cahier 96 pages petit format – 56g – seyès calligraphe · 450 F
A40: Cahier de travaux pratiques 200 pages | B40: 1 | C40: 1 | D40: 1 | E40: 1729 · Cahier de travaux pratiques MyFriend 200 pages · 1 300 F | F40: 1729 · Cahier de travaux pratiques MyFriend 200 pages · 1 300 F | G40: 1729 · Cahier de travaux pratiques MyFriend 200 pages · 1 300 F
A41: Cahier de dessin | B41: 1 | C41: 1 | D41: 1 | E41: 1572 · Cahier de dessin L'écolier 32 pages · 250 F | F41: 1286 · Cahier de dessin TPG · 550 F | G41: 1286 · Cahier de dessin TPG · 550 F
A42: Ardoise blanche avec feutre | B42: 1 | C42: 1 | D42: 1 | E42: 33 · Ardoise blanche + feutre effaçable · 1 200 F | F42: 33 · Ardoise blanche + feutre effaçable · 1 200 F | G42: 33 · Ardoise blanche + feutre effaçable · 1 200 F
A43: Feutres pour ardoise | B43: 2 | C43: 2 | D43: 4 | E43: 1698 · Marqueur tableau blanc BEIYUE B-105 · 400 F | F43: 1698 · Marqueur tableau blanc BEIYUE B-105 · 400 F | G43: 1698 · Marqueur tableau blanc BEIYUE B-105 · 400 F
A44: Effaceur d'ardoise | B44: 1 | C44: 1 | D44: 1 | E44: 1244 · Brosse tableau blanc magnetique RX T-29 · 400 F | F44: 1244 · Brosse tableau blanc magnetique RX T-29 · 400 F | G44: 1244 · Brosse tableau blanc magnetique RX T-29 · 400 F
...

Sheet Contenu des kits
A1: Cycle | B1: Classe | C1: Gamme | D1: Ordre | E1: Groupe d'affichage | F1: Libellé (vu par le client) | G1: ID produit | H1: Produit au catalogue | I1: Quantité | J1: Prix unitaire | K1: Section | L1: Coché | M1: Total ligne | N1: Statut | O1: Note | P1: Fournisseur | Q1: Délai | R1: Prix d'achat | S1: Coût ligne | T1: Bénéfice ligne | U1: Montant sans prix d'achat
A2: Préscolaire | B2: Petite section | C2: Essentiel | D2: 1 | E2: Cahiers | F2: Cahier de travaux pratiques 100 pages | G2: 1728 | H2: Cahier de travaux pratiques MyFriend 100 pages | I2: 1 | J2: 900 | K2: Principal | L2: Oui | M2: =IF(AND(L2="Oui",K2="Principal"),I2*J2,0) -> 900 | N2: OK | O2: Cahier de graphisme | P2: LPD | Q2: 24h | S2: =IF(AND(L2="Oui",K2="Principal",R2<>""),I2*R2,0) -> 0 | T2: =IF(R2<>"",M2-S2,0) -> 0 | U2: =IF(R2="",M2,0) -> 900
A3: Préscolaire | B3: Petite section | C3: Essentiel | D3: 2 | E3: Cahiers | F3: Cahier de travaux pratiques 200 pages | G3: 1729 | H3: Cahier de travaux pratiques MyFriend 200 pages | I3: 1 | J3: 1300 | K3: Principal | L3: Oui | M3: =IF(AND(L3="Oui",K3="Principal"),I3*J3,0) -> 1300 | N3: OK | O3: Cahier de vie | P3: LPD | Q3: 24h | S3: =IF(AND(L3="Oui",K3="Principal",R3<>""),I3*R3,0) -> 0 | T3: =IF(R3<>"",M3-S3,0) -> 0 | U3: =IF(R3="",M3,0) -> 1300
A4: Préscolaire | B4: Petite section | C4: Essentiel | D4: 3 | E4: Art & dessin | F4: Cahier de dessin | G4: 1572 | H4: Cahier de dessin L'écolier 32 pages | I4: 1 | J4: 250 | K4: Principal | L4: Oui | M4: =IF(AND(L4="Oui",K4="Principal"),I4*J4,0) -> 250 | N4: OK | P4: Papex | Q4: 6j | R4: 150 | S4: =IF(AND(L4="Oui",K4="Principal",R4<>""),I4*R4,0) -> 150 | T4: =IF(R4<>"",M4-S4,0) -> 100 | U4: =IF(R4="",M4,0) -> 0
A5: Préscolaire | B5: Petite section | C5: Essentiel | D5: 4 | E5: Ardoise | F5: Ardoise blanche avec feutre | G5: 33 | H5: Ardoise blanche + feutre effaçable | I5: 1 | J5: 1200 | K5: Principal | L5: Oui | M5: =IF(AND(L5="Oui",K5="Principal"),I5*J5,0) -> 1200 | N5: OK | P5: SacAdo | Q5: 24h | S5: =IF(AND(L5="Oui",K5="Principal",R5<>""),I5*R5,0) -> 0 | T5: =IF(R5<>"",M5-S5,0) -> 0 | U5: =IF(R5="",M5,0) -> 1200
A6: Préscolaire | B6: Petite section | C6: Essentiel | D6: 5 | E6: Ardoise | F6: Feutres pour ardoise | G6: 1698 | H6: Marqueur tableau blanc BEIYUE B-105 | I6: 2 | J6: 400 | K6: Principal | L6: Oui | M6: =IF(AND(L6="Oui",K6="Principal"),I6*J6,0) -> 800 | N6: OK | P6: Cissé & Frères | Q6: 6j | S6: =IF(AND(L6="Oui",K6="Principal",R6<>""),I6*R6,0) -> 0 | T6: =IF(R6<>"",M6-S6,0) -> 0 | U6: =IF(R6="",M6,0) -> 800
A7: Préscolaire | B7: Petite section | C7: Essentiel | D7: 6 | E7: Ardoise | F7: Effaceur d'ardoise | G7: 1244 | H7: Brosse tableau blanc magnetique RX T-29 | I7: 1 | J7: 400 | K7: Principal | L7: Oui | M7: =IF(AND(L7="Oui",K7="Principal"),I7*J7,0) -> 400 | N7: OK | P7: LPD | Q7: 6j | R7: 130 | S7: =IF(AND(L7="Oui",K7="Principal",R7<>""),I7*R7,0) -> 130 | T7: =IF(R7<>"",M7-S7,0) -> 270 | U7: =IF(R7="",M7,0) -> 0
A8: Préscolaire | B8: Petite section | C8: Essentiel | D8: 7 | E8: Écriture | F8: Crayon à papier HB | G8: 1571 | H8: Crayon papier couleur du Senegal - a l unite | I8: 2 | J8: 75 | K8: Principal | L8: Oui | M8: =IF(AND(L8="Oui",K8="Principal"),I8*J8,0) -> 150 | N8: OK | P8: LPD | Q8: 6j | S8: =IF(AND(L8="Oui",K8="Principal",R8<>""),I8*R8,0) -> 0 | T8: =IF(R8<>"",M8-S8,0) -> 0 | U8: =IF(R8="",M8,0) -> 150
A9: Préscolaire | B9: Petite section | C9: Essentiel | D9: 8 | E9: Petit matériel | F9: Gomme | G9: 9 | H9: Gomme blanche | I9: 1 | J9: 150 | K9: Principal | L9: Oui | M9: =IF(AND(L9="Oui",K9="Principal"),I9*J9,0) -> 150 | N9: OK | P9: SacAdo | Q9: 24h | S9: =IF(AND(L9="Oui",K9="Principal",R9<>""),I9*R9,0) -> 0 | T9: =IF(R9<>"",M9-S9,0) -> 0 | U9: =IF(R9="",M9,0) -> 150
A10: Préscolaire | B10: Petite section | C10: Essentiel | D10: 9 | E10: Petit matériel | F10: Taille-crayon avec réservoir | G10: 1587 | H10: Tailla Crayon 1 Trou + Réservoir Clean – MAPED | I10: 1 | J10: 500 | K10: Principal | L10: Oui | M10: =IF(AND(L10="Oui",K10="Principal"),I10*J10,0) -> 500 | N10: OK | P10: Papex | Q10: 6j | R10: 350 | S10: =IF(AND(L10="Oui",K10="Principal",R10<>""),I10*R10,0) -> 350 | T10: =IF(R10<>"",M10-S10,0) -> 150 | U10: =IF(R10="",M10,0) -> 0
A11: Préscolaire | B11: Petite section | C11: Essentiel | D11: 10 | E11: Art & dessin | F11: Crayons de couleur | G11: 1589 | H11: Crayon Couleur BTE X12 – MAPED | I11: 1 | J11: 900 | K11: Principal | L11: Oui | M11: =IF(AND(L11="Oui",K11="Principal"),I11*J11,0) -> 900 | N11: OK | P11: Papex | Q11: 6j | R11: 650 | S11: =IF(AND(L11="Oui",K11="Principal",R11<>""),I11*R11,0) -> 650 | T11: =IF(R11<>"",M11-S11,0) -> 250 | U11: =IF(R11="",M11,0) -> 0
A12: Préscolaire | B12: Petite section | C12: Essentiel | D12: 11 | E12: Petit matériel | F12: Bâtons de colle | G12: 1173 | H12: Baton de colle Dolphin Stick Glue | I12: 2 | J12: 570 | K12: Principal | L12: Oui | M12: =IF(AND(L12="Oui",K12="Principal"),I12*J12,0) -> 1140 | N12: OK | P12: LPD | Q12: 6j | R12: 420 | S12: =IF(AND(L12="Oui",K12="Principal",R12<>""),I12*R12,0) -> 840 | T12: =IF(R12<>"",M12-S12,0) -> 300 | U12: =IF(R12="",M12,0) -> 0
A13: Préscolaire | B13: Petite section | C13: Essentiel | D13: 12 | E13: Petit matériel | F13: Ciseaux à bouts ronds | G13: 1250 | H13: Ciseaux scolaires bouts ronds | I13: 1 | J13: 250 | K13: Principal | L13: Oui | M13: =IF(AND(L13="Oui",K13="Principal"),I13*J13,0) -> 250 | N13: OK | P13: LPD | Q13: 6j | R13: 100 | S13: =IF(AND(L13="Oui",K13="Principal",R13<>""),I13*R13,0) -> 100 | T13: =IF(R13<>"",M13-S13,0) -> 150 | U13: =IF(R13="",M13,0) -> 0
A14: Préscolaire | B14: Petite section | C14: Essentiel | D14: 13 | E14: Rangement | F14: Pochette à élastique | G14: 1625 | H14: Chemise. 3 rabats élastiques + étiquettes 4,5/10ème assorties | I14: 1 | J14: 500 | K14: Principal | L14: Oui | M14: =IF(AND(L14="Oui",K14="Principal"),I14*J14,0) -> 500 | N14: OK | P14: Papex | Q14: 6j | S14: =IF(AND(L14="Oui",K14="Principal",R14<>""),I14*R14,0) -> 0 | T14: =IF(R14<>"",M14-S14,0) -> 0 | U14: =IF(R14="",M14,0) -> 500
A15: Préscolaire | B15: Petite section | C15: Essentiel | D15: 14 | E15: Accessoires | F15: Trousse Hello | G15: 1706 | H15: Trousse Hello monstre vert | I15: 1 | J15: 2000 | K15: Principal | L15: Oui | M15: =IF(AND(L15="Oui",K15="Principal"),I15*J15,0) -> 2000 | N15: OK | P15: Cissé & Frères | Q15: 6j | R15: 1500 | S15: =IF(AND(L15="Oui",K15="Principal",R15<>""),I15*R15,0) -> 1500 | T15: =IF(R15<>"",M15-S15,0) -> 500 | U15: =IF(R15="",M15,0) -> 0
A16: Préscolaire | B16: Petite section | C16: Essentiel | D16: 15 | E16: Accessoires | F16: Gourde | G16: 1287 | H16: Gourde Drink violette | I16: 1 | J16: 2500 | K16: Principal | L16: Oui | M16: =IF(AND(L16="Oui",K16="Principal"),I16*J16,0) -> 2500 | N16: OK | O16: Nouveau prix : 2 500 F (ancien 2 000 F), à changer dans l'admin | P16: LPD | Q16: 6j | R16: 1800 | S16: =IF(AND(L16="Oui",K16="Principal",R16<>""),I16*R16,0) -> 1800 | T16: =IF(R16<>"",M16-S16,0) -> 700 | U16: =IF(R16="",M16,0) -> 0
A17: Préscolaire | B17: Petite section | C17: Essentiel | D17: 16 | E17: Option | F17: Cartable | G17: 1252 | H17: Cartable Kam Rad Cute Capybaras | I17: 1 | J17: 6500 | K17: Option | L17: Non | M17: =IF(AND(L17="Oui",K17="Principal"),I17*J17,0) -> 0 | N17: OK | P17: LPD | Q17: 6j | R17: 6000 | S17: =IF(AND(L17="Oui",K17="Principal",R17<>""),I17*R17,0) -> 0 | T17: =IF(R17<>"",M17-S17,0) -> 0 | U17: =IF(R17="",M17,0) -> 0
A18: Préscolaire | B18: Petite section | C18: Complet | D18: 1 | E18: Cahiers | F18: Cahier de travaux pratiques 100 pages | G18: 1728 | H18: Cahier de travaux pratiques MyFriend 100 pages | I18: 1 | J18: 900 | K18: Principal | L18: Oui | M18: =IF(AND(L18="Oui",K18="Principal"),I18*J18,0) -> 900 | N18: OK | O18: Cahier de graphisme | P18: LPD | Q18: 24h | S18: =IF(AND(L18="Oui",K18="Principal",R18<>""),I18*R18,0) -> 0 | T18: =IF(R18<>"",M18-S18,0) -> 0 | U18: =IF(R18="",M18,0) -> 900
A19: Préscolaire | B19: Petite section | C19: Complet | D19: 2 | E19: Cahiers | F19: Cahier de travaux pratiques 200 pages | G19: 1729 | H19: Cahier de travaux pratiques MyFriend 200 pages | I19: 1 | J19: 1300 | K19: Principal | L19: Oui | M19: =IF(AND(L19="Oui",K19="Principal"),I19*J19,0) -> 1300 | N19: OK | O19: Cahier de vie | P19: LPD | Q19: 24h | S19: =IF(AND(L19="Oui",K19="Principal",R19<>""),I19*R19,0) -> 0 | T19: =IF(R19<>"",M19-S19,0) -> 0 | U19: =IF(R19="",M19,0) -> 1300
A20: Préscolaire | B20: Petite section | C20: Complet | D20: 3 | E20: Art & dessin | F20: Cahier de dessin | G20: 1286 | H20: Cahier de dessin TPG | I20: 1 | J20: 550 | K20: Principal | L20: Oui | M20: =IF(AND(L20="Oui",K20="Principal"),I20*J20,0) -> 550 | N20: OK | P20: LPD | Q20: 6j | R20: 450 | S20: =IF(AND(L20="Oui",K20="Principal",R20<>""),I20*R20,0) -> 450 | T20: =IF(R20<>"",M20-S20,0) -> 100 | U20: =IF(R20="",M20,0) -> 0
A21: Préscolaire | B21: Petite section | C21: Complet | D21: 4 | E21: Ardoise | F21: Ardoise blanche avec feutre | G21: 33 | H21: Ardoise blanche + feutre effaçable | I21: 1 | J21: 1200 | K21: Principal | L21: Oui | M21: =IF(AND(L21="Oui",K21="Principal"),I21*J21,0) -> 1200 | N21: OK | P21: SacAdo | Q21: 24h | S21: =IF(AND(L21="Oui",K21="Principal",R21<>""),I21*R21,0) -> 0 | T21: =IF(R21<>"",M21-S21,0) -> 0 | U21: =IF(R21="",M21,0) -> 1200
A22: Préscolaire | B22: Petite section | C22: Complet | D22: 5 | E22: Ardoise | F22: Feutres pour ardoise | G22: 1698 | H22: Marqueur tableau blanc BEIYUE B-105 | I22: 2 | J22: 400 | K22: Principal | L22: Oui | M22: =IF(AND(L22="Oui",K22="Principal"),I22*J22,0) -> 800 | N22: OK | P22: Cissé & Frères | Q22: 6j | S22: =IF(AND(L22="Oui",K22="Principal",R22<>""),I22*R22,0) -> 0 | T22: =IF(R22<>"",M22-S22,0) -> 0 | U22: =IF(R22="",M22,0) -> 800
A23: Préscolaire | B23: Petite section | C23: Complet | D23: 6 | E23: Ardoise | F23: Effaceur d'ardoise | G23: 1244 | H23: Brosse tableau blanc magnetique RX T-29 | I23: 1 | J23: 400 | K23: Principal | L23: Oui | M23: =IF(AND(L23="Oui",K23="Principal"),I23*J23,0) -> 400 | N23: OK | P23: LPD | Q23: 6j | R23: 130 | S23: =IF(AND(L23="Oui",K23="Principal",R23<>""),I23*R23,0) -> 130 | T23: =IF(R23<>"",M23-S23,0) -> 270 | U23: =IF(R23="",M23,0) -> 0
A24: Préscolaire | B24: Petite section | C24: Complet | D24: 7 | E24: Écriture | F24: Crayon à papier HB | G24: 1571 | H24: Crayon papier couleur du Senegal - a l unite | I24: 2 | J24: 75 | K24: Principal | L24: Oui | M24: =IF(AND(L24="Oui",K24="Principal"),I24*J24,0) -> 150 | N24: OK | P24: LPD | Q24: 6j | S24: =IF(AND(L24="Oui",K24="Principal",R24<>""),I24*R24,0) -> 0 | T24: =IF(R24<>"",M24-S24,0) -> 0 | U24: =IF(R24="",M24,0) -> 150
A25: Préscolaire | B25: Petite section | C25: Complet | D25: 8 | E25: Petit matériel | F25: Gomme | G25: 1181 | H25: Gomme Staedtler Mars Plastic | I25: 1 | J25: 250 | K25: Principal | L25: Oui | M25: =IF(AND(L25="Oui",K25="Principal"),I25*J25,0) -> 250 | N25: OK | P25: LPD | Q25: 6j | R25: 110 | S25: =IF(AND(L25="Oui",K25="Principal",R25<>""),I25*R25,0) -> 110 | T25: =IF(R25<>"",M25-S25,0) -> 140 | U25: =IF(R25="",M25,0) -> 0
A26: Préscolaire | B26: Petite section | C26: Complet | D26: 9 | E26: Petit matériel | F26: Taille-crayon avec réservoir | G26: 1587 | H26: Tailla Crayon 1 Trou + Réservoir Clean – MAPED | I26: 1 | J26: 500 | K26: Principal | L26: Oui | M26: =IF(AND(L26="Oui",K26="Principal"),I26*J26,0) -> 500 | N26: OK | P26: Papex | Q26: 6j | R26: 350 | S26: =IF(AND(L26="Oui",K26="Principal",R26<>""),I26*R26,0) -> 350 | T26: =IF(R26<>"",M26-S26,0) -> 150 | U26: =IF(R26="",M26,0) -> 0
A27: Préscolaire | B27: Petite section | C27: Complet | D27: 10 | E27: Art & dessin | F27: Crayons de couleur | G27: 1589 | H27: Crayon Couleur BTE X12 – MAPED | I27: 1 | J27: 900 | K27: Principal | L27: Oui | M27: =IF(AND(L27="Oui",K27="Principal"),I27*J27,0) -> 900 | N27: OK | P27: Papex | Q27: 6j | R27: 650 | S27: =IF(AND(L27="Oui",K27="Principal",R27<>""),I27*R27,0) -> 650 | T27: =IF(R27<>"",M27-S27,0) -> 250 | U27: =IF(R27="",M27,0) -> 0
A28: Préscolaire | B28: Petite section | C28: Complet | D28: 11 | E28: Petit matériel | F28: Bâtons de colle | G28: 1604 | H28: Bâton de colle 20 g – GIOTTO | I28: 2 | J28: 700 | K28: Principal | L28: Oui | M28: =IF(AND(L28="Oui",K28="Principal"),I28*J28,0) -> 1400 | N28: OK | P28: Papex | Q28: 6j | R28: 400 | S28: =IF(AND(L28="Oui",K28="Principal",R28<>""),I28*R28,0) -> 800 | T28: =IF(R28<>"",M28-S28,0) -> 600 | U28: =IF(R28="",M28,0) -> 0
A29: Préscolaire | B29: Petite section | C29: Complet | D29: 12 | E29: Petit matériel | F29: Ciseaux à bouts ronds | G29: 1586 | H29: Ciseaux 13cm Security Stop – MAPED | I29: 1 | J29: 900 | K29: Principal | L29: Oui | M29: =IF(AND(L29="Oui",K29="Principal"),I29*J29,0) -> 900 | N29: OK | P29: Papex | Q29: 6j | R29: 650 | S29: =IF(AND(L29="Oui",K29="Principal",R29<>""),I29*R29,0) -> 650 | T29: =IF(R29<>"",M29-S29,0) -> 250 | U29: =IF(R29="",M29,0) -> 0
