Workbook

Sheet Lisez-moi
A1: Kits SacAdo : du CI à la Terminale (L, S1, S2, STEG)
A2: Version 10 du 26/09/2026. Même contenu que kits.json.
A4: Les trois gammes, de la moins chère à la plus chère
A5: Essentiel : les fournitures indispensables, avec l'article correct le moins cher. Les livres du Complet sont affichés en dessous, décochés : le client peut les ajouter.
A6: Complet : toute la liste en fournitures de meilleure qualité (Calligraphe, Maped), plus les œuvres au programme, et au primaire les manuels Didactikos de la liste. Calculatrice scientifique générique. Collège, lycée et STEG : un protège-cahier par cahier.
A7: Confort : le Complet, plus les manuels scolaires (collège et lycée), la Casio fx-92 à la place de la calculatrice générique, stylo 4 couleurs, correcteur, et des livres en plus : œuvres « bon à avoir » en L, La Clé des Cracks et parascolaire scientifique en 3e et en S (éditions S1 ou S2 selon la série).
A8: Dans chaque kit, chaque produit peut être décoché (colonne « Coché par défaut »). Sac en option décochée. Pas d'ebook pour l'instant.
A10: À faire avant publication
A11: 1. Reporter dans Articles l'ID et le prix de l'app pour les copies doubles et les deux Calligraphe grand format (lignes A-CREER).
A12: 2. Livres Korka Diallo (lignes CDC) : titres et prix réels du catalogue Korka depuis le 26/09.
A13: 3. Corriger les prix signalés dans la feuille Écarts Edushop (lignes orange).
A15: Séries techniques
... A29: Feuilles de classe : ID et quantité (en bleu) modifiables. Statut vente : « Fixé », « Estimé », « À trancher », « À fournir ». Statut achat : « Confirmé », « Estimé », « Inconnu ».

Sheet Récap
A1: Classe | B1: Gamme | C1: Nb de lignes | D1: Nb de cahiers | E1: Total vente (FCFA) | F1: Coût de revient connu (FCFA) | G1: Marge sur coût connu (FCFA) | H1: Part du PV estimée | I1: Statut | J1: Nb de manquants | K1: Essentiel + livres cochés (FCFA)
A2: CI | B2: Essentiel | C2: =COUNTA(CI!C6:C12) -> 7 | D2: =CI!H18 -> 2 | E2: =CI!H14 -> 4225 | F2: =CI!H15 -> 1600 | G2: =CI!H17 -> 750 | H2: =CI!H19 -> 0.34319527 | I2: =CI!H20 -> Coût incomplet : 4 ligne(s) sans prix d'achat | J2: 1 | K2: =CI!H26 -> 15895
A3: CI | B3: Complet | C3: =COUNTA(CI!C33:C42) -> 10 | D3: =CI!H48 -> 2 | E3: =CI!H44 -> 18995 | F3: =CI!H45 -> 12570 | G3: =CI!H47 -> 4650 | H3: =CI!H49 -> 0.084232693 | I3: =CI!H50 -> Coût incomplet : 3 ligne(s) sans prix d'achat | J3: 1
A4: CI | B4: Confort | C4: =COUNTA(CI!C57:C68) -> 12 | D4: =CI!H74 -> 2 | E4: =CI!H70 -> 24575 | F4: =CI!H71 -> 16150 | G4: =CI!H73 -> 6650 | H4: =CI!H75 -> 0.065106816 | I4: =CI!H76 -> Coût incomplet : 3 ligne(s) sans prix d'achat | J4: 1
A5: CP | B5: Essentiel | C5: =COUNTA(CP!C6:C12) -> 7 | D5: =CP!H18 -> 2 | E5: =CP!H14 -> 4000 | F5: =CP!H15 -> 2600 | G5: =CP!H17 -> 1000 | H5: =CP!H19 -> 0.45 | I5: =CP!H20 -> Coût incomplet : 3 ligne(s) sans prix d'achat | J5: 0 | K5: =CP!H26 -> 15670
A6: CP | B6: Complet | C6: =COUNTA(CP!C33:C42) -> 10 | D6: =CP!H48 -> 2 | E6: =CP!H44 -> 19920 | F6: =CP!H45 -> 14670 | G6: =CP!H47 -> 4950 | H6: =CP!H49 -> 0.17068273 | I6: =CP!H50 -> Coût incomplet : 2 ligne(s) sans prix d'achat | J6: 0
A7: CP | B7: Confort | C7: =COUNTA(CP!C57:C68) -> 12 | D7: =CP!H74 -> 2 | E7: =CP!H70 -> 25500 | F7: =CP!H71 -> 18250 | G7: =CP!H73 -> 6950 | H7: =CP!H75 -> 0.13333333 | I7: =CP!H76 -> Coût incomplet : 2 ligne(s) sans prix d'achat | J7: 0
A8: CE1 | B8: Essentiel | C8: =COUNTA(CE1!C6:C13) -> 8 | D8: =CE1!H19 -> 4 | E8: =CE1!H15 -> 5025 | F8: =CE1!H16 -> 3410 | G8: =CE1!H18 -> 1340 | H8: =CE1!H20 -> 0.35820896 | I8: =CE1!H21 -> Coût incomplet : 3 ligne(s) sans prix d'achat | J8: 0 | K8: =CE1!H27 -> 17025
A9: CE1 | B9: Complet | C9: =COUNTA(CE1!C34:C44) -> 11 | D9: =CE1!H50 -> 4 | E9: =CE1!H46 -> 21425 | F9: =CE1!H47 -> 16010 | G9: =CE1!H49 -> 5140 | H9: =CE1!H51 -> 0.15869312 | I9: =CE1!H52 -> Coût incomplet : 3 ligne(s) sans prix d'achat | J9: 0
A10: CE1 | B10: Confort | C10: =COUNTA(CE1!C59:C71) -> 13 | D10: =CE1!H77 -> 4 | E10: =CE1!H73 -> 27445 | F10: =CE1!H74 -> 20030 | G10: =CE1!H76 -> 7140 | H10: =CE1!H78 -> 0.12388413 | I10: =CE1!H79 -> Coût incomplet : 3 ligne(s) sans prix d'achat | J10: 0
A11: CE2 | B11: Essentiel | C11: =COUNTA(CE2!C6:C13) -> 8 | D11: =CE2!H19 -> 4 | E11: =CE2!H15 -> 5025 | F11: =CE2!H16 -> 3410 | G11: =CE2!H18 -> 1340 | H11: =CE2!H20 -> 0.35820896 | I11: =CE2!H21 -> Coût incomplet : 3 ligne(s) sans prix d'achat | J11: 0 | K11: =CE2!H27 -> 17025
A12: CE2 | B12: Complet | C12: =COUNTA(CE2!C34:C44) -> 11 | D12: =CE2!H50 -> 4 | E12: =CE2!H46 -> 21425 | F12: =CE2!H47 -> 16010 | G12: =CE2!H49 -> 5140 | H12: =CE2!H51 -> 0.15869312 | I12: =CE2!H52 -> Coût incomplet : 3 ligne(s) sans prix d'achat | J12: 0
A13: CE2 | B13: Confort | C13: =COUNTA(CE2!C59:C71) -> 13 | D13: =CE2!H77 -> 4 | E13: =CE2!H73 -> 27445 | F13: =CE2!H74 -> 20030 | G13: =CE2!H76 -> 7140 | H13: =CE2!H78 -> 0.12388413 | I13: =CE2!H79 -> Coût incomplet : 3 ligne(s) sans prix d'achat | J13: 0
A14: CM1 | B14: Essentiel | C14: =COUNTA(CM1!C6:C13) -> 8 | D14: =CM1!H19 -> 4 | E14: =CM1!H15 -> 5025 | F14: =CM1!H16 -> 3410 | G14: =CM1!H18 -> 1340 | H14: =CM1!H20 -> 0.35820896 | I14: =CM1!H21 -> Coût incomplet : 3 ligne(s) sans prix d'achat | J14: 0 | K14: =CM1!H27 -> 17025
A15: CM1 | B15: Complet | C15: =COUNTA(CM1!C34:C44) -> 11 | D15: =CM1!H50 -> 4 | E15: =CM1!H46 -> 21425 | F15: =CM1!H47 -> 16010 | G15: =CM1!H49 -> 5140 | H15: =CM1!H51 -> 0.15869312 | I15: =CM1!H52 -> Coût incomplet : 3 ligne(s) sans prix d'achat | J15: 0
A16: CM1 | B16: Confort | C16: =COUNTA(CM1!C59:C71) -> 13 | D16: =CM1!H77 -> 4 | E16: =CM1!H73 -> 27905 | F16: =CM1!H74 -> 20490 | G16: =CM1!H76 -> 7140 | H16: =CM1!H78 -> 0.12184196 | I16: =CM1!H79 -> Coût incomplet : 3 ligne(s) sans prix d'achat | J16: 0
A17: CM2 | B17: Essentiel | C17: =COUNTA(CM2!C6:C13) -> 8 | D17: =CM2!H19 -> 4 | E17: =CM2!H15 -> 5025 | F17: =CM2!H16 -> 3410 | G17: =CM2!H18 -> 1340 | H17: =CM2!H20 -> 0.35820896 | I17: =CM2!H21 -> Coût incomplet : 3 ligne(s) sans prix d'achat | J17: 0 | K17: =CM2!H27 -> 17025
A18: CM2 | B18: Complet | C18: =COUNTA(CM2!C34:C44) -> 11 | D18: =CM2!H50 -> 4 | E18: =CM2!H46 -> 21425 | F18: =CM2!H47 -> 16010 | G18: =CM2!H49 -> 5140 | H18: =CM2!H51 -> 0.15869312 | I18: =CM2!H52 -> Coût incomplet : 3 ligne(s) sans prix d'achat | J18: 0
A19: CM2 | B19: Confort | C19: =COUNTA(CM2!C59:C71) -> 13 | D19: =CM2!H77 -> 4 | E19: =CM2!H73 -> 30575 | F19: =CM2!H74 -> 23160 | G19: =CM2!H76 -> 7140 | H19: =CM2!H78 -> 0.11120196 | I19: =CM2!H79 -> Coût incomplet : 3 ligne(s) sans prix d'achat | J19: 0
A20: 6e | B20: Essentiel | C20: =COUNTA(6e!C6:C26) -> 21 | D20: =6e!H32 -> 11 | E20: =6e!H28 -> 11550 | F20: =6e!H29 -> 8135 | G20: =6e!H31 -> 2940 | H20: =6e!H33 -> 0.56926407 | I20: =6e!H34 -> Coût incomplet : 2 ligne(s) sans prix d'achat | J20: 0 | K20: =6e!H38 -> 15050
A21: 6e | B21: Complet | C21: =COUNTA(6e!C45:C70) -> 26 | D21: =6e!H76 -> 11 | E21: =6e!H72 -> 29625 | F21: =6e!H73 -> 22160 | G21: =6e!H75 -> 4890 | H21: =6e!H77 -> 0.27004219 | I21: =6e!H78 -> Total incomplet : 1 prix de vente à fournir | J21: 2
A22: 6e | B22: Confort | C22: =COUNTA(6e!C86:C121) -> 36 | D22: =6e!H127 -> 11 | E22: =6e!H123 -> 61855 | F22: =6e!H124 -> 46340 | G22: =6e!H126 -> 12940 | H22: =6e!H128 -> 0.12933473 | I22: =6e!H129 -> Total incomplet : 1 prix de vente à fournir | J22: 5
A23: 5e | B23: Essentiel | C23: =COUNTA(5e!C6:C26) -> 21 | D23: =5e!H32 -> 11 | E23: =5e!H28 -> 11550 | F23: =5e!H29 -> 8135 | G23: =5e!H31 -> 2940 | H23: =5e!H33 -> 0.56926407 | I23: =5e!H34 -> Coût incomplet : 2 ligne(s) sans prix d'achat | J23: 0 | K23: =5e!H38 -> 15050
A24: 5e | B24: Complet | C24: =COUNTA(5e!C45:C70) -> 26 | D24: =5e!H76 -> 11 | E24: =5e!H72 -> 29625 | F24: =5e!H73 -> 22160 | G24: =5e!H75 -> 4890 | H24: =5e!H77 -> 0.27004219 | I24: =5e!H78 -> Total incomplet : 1 prix de vente à fournir | J24: 2
A25: 5e | B25: Confort | C25: =COUNTA(5e!C86:C123) -> 38 | D25: =5e!H129 -> 11 | E25: =5e!H125 -> 68655 | F25: =5e!H126 -> 51140 | G25: =5e!H128 -> 14940 | H25: =5e!H130 -> 0.11652465 | I25: =5e!H131 -> Total incomplet : 1 prix de vente à fournir | J25: 3
A26: 4e | B26: Essentiel | C26: =COUNTA(4e!C6:C28) -> 23 | D26: =4e!H34 -> 13 | E26: =4e!H30 -> 14025 | F26: =4e!H31 -> 10110 | G26: =4e!H33 -> 3440 | H26: =4e!H35 -> 0.44919786 | I26: =4e!H36 -> Coût incomplet : 2 ligne(s) sans prix d'achat | J26: 0 | K26: =4e!H40 -> 17525
A27: 4e | B27: Complet | C27: =COUNTA(4e!C47:C74) -> 28 | D27: =4e!H80 -> 13 | E27: =4e!H76 -> 33125 | F27: =4e!H77 -> 24860 | G27: =4e!H79 -> 5390 | H27: =4e!H81 -> 0.24150943 | I27: =4e!H82 -> Total incomplet : 1 prix de vente à fournir | J27: 3
A28: 4e | B28: Confort | C28: =COUNTA(4e!C91:C130) -> 40 | D28: =4e!H136 -> 13 | E28: =4e!H132 -> 79445 | F28: =4e!H133 -> 60430 | G28: =4e!H135 -> 16140 | H28: =4e!H137 -> 0.1006986 | I28: =4e!H138 -> Total incomplet : 1 prix de vente à fournir | J28: 5
A29: 3e | B29: Essentiel | C29: =COUNTA(3e!C6:C29) -> 24 | D29: =3e!H35 -> 13 | E29: =3e!H31 -> 14075 | F29: =3e!H32 -> 10160 | G29: =3e!H34 -> 3440 | H29: =3e!H36 -> 0.48312611 | I29: =3e!H37 -> Coût incomplet : 2 ligne(s) sans prix d'achat | J29: 0 | K29: =3e!H42 -> 20375
A30: 3e | B30: Complet | C30: =COUNTA(3e!C49:C78) -> 30 | D30: =3e!H84 -> 13 | E30: =3e!H80 -> 36675 | F30: =3e!H81 -> 27510 | G30: =3e!H83 -> 6440 | H30: =3e!H85 -> 0.21813224 | I30: =3e!H86 -> Total incomplet : 1 prix de vente à fournir | J30: 2
A31: 3e | B31: Confort | C31: =COUNTA(3e!C94:C138) -> 45 | D31: =3e!H144 -> 13 | E31: =3e!H140 -> 101095 | F31: =3e!H141 -> 77580 | G31: =3e!H143 -> 20790 | H31: =3e!H145 -> 0.079133488 | I31: =3e!H146 -> Total incomplet : 1 prix de vente à fournir | J31: 4
A32: 2nde L | B32: Essentiel | C32: =COUNTA('2nde L'!C6:C28) -> 23 | D32: ='2nde L'!H34 -> 13 | E32: ='2nde L'!H30 -> 13925 | F32: ='2nde L'!H31 -> 10110 | G32: ='2nde L'!H33 -> 3340 | H32: ='2nde L'!H35 -> 0.56014363 | I32: ='2nde L'!H36 -> Coût incomplet : 2 ligne(s) sans prix d'achat | J32: 0 | K32: ='2nde L'!H40 -> 17825
A33: 2nde L | B33: Complet | C33: =COUNTA('2nde L'!C47:C75) -> 29 | D33: ='2nde L'!H81 -> 13 | E33: ='2nde L'!H77 -> 36675 | F33: ='2nde L'!H78 -> 28560 | G33: ='2nde L'!H80 -> 6540 | H33: ='2nde L'!H82 -> 0.21813224 | I33: ='2nde L'!H83 -> Total incomplet : 1 prix de vente à fournir | J33: 2
A34: 2nde L | B34: Confort | C34: =COUNTA('2nde L'!C91:C126) -> 36 | D34: ='2nde L'!H132 -> 13 | E34: ='2nde L'!H128 -> 64725 | F34: ='2nde L'!H129 -> 50360 | G34: ='2nde L'!H131 -> 12790 | H34: ='2nde L'!H133 -> 0.12359985 | I34: ='2nde L'!H134 -> Total incomplet : 1 prix de vente à fournir | J34: 4
A35: 2nde S | B35: Essentiel | C35: =COUNTA('2nde S'!C6:C26) -> 21 | D35: ='2nde S'!H32 -> 12 | E35: ='2nde S'!H28 -> 13525 | F35: ='2nde S'!H29 -> 9810 | G35: ='2nde S'!H31 -> 3240 | H35: ='2nde S'!H33 -> 0.61367837 | I35: ='2nde S'!H34 -> Coût incomplet : 2 ligne(s) sans prix d'achat | J35: 0 | K35: ='2nde S'!H38 -> 17425
A36: 2nde S | B36: Complet | C36: =COUNTA('2nde S'!C45:C71) -> 27 | D36: ='2nde S'!H77 -> 12 | E36: ='2nde S'!H73 -> 36225 | F36: ='2nde S'!H74 -> 28260 | G36: ='2nde S'!H76 -> 6690 | H36: ='2nde S'!H78 -> 0.22084196 | I36: ='2nde S'!H79 -> Total incomplet : 1 prix de vente à fournir | J36: 3
A37: 2nde S | B37: Confort | C37: =COUNTA('2nde S'!C88:C122) -> 35 | D37: ='2nde S'!H128 -> 12 | E37: ='2nde S'!H124 -> 93675 | F37: ='2nde S'!H125 -> 74460 | G37: ='2nde S'!H127 -> 17940 | H37: ='2nde S'!H129 -> 0.085401655 | I37: ='2nde S'!H130 -> Total incomplet : 1 prix de vente à fournir | J37: 3
A38: 1re L | B38: Essentiel | C38: =COUNTA('1re L'!C6:C28) -> 23 | D38: ='1re L'!H34 -> 12 | E38: ='1re L'!H30 -> 13425 | F38: ='1re L'!H31 -> 9710 | G38: ='1re L'!H33 -> 3240 | H38: ='1re L'!H35 -> 0.54376164 | I38: ='1re L'!H36 -> Coût incomplet : 2 ligne(s) sans prix d'achat | J38: 0 | K38: ='1re L'!H42 -> 21825
A39: 1re L | B39: Complet | C39: =COUNTA('1re L'!C49:C79) -> 31 | D39: ='1re L'!H85 -> 12 | E39: ='1re L'!H81 -> 39825 | F39: ='1re L'!H82 -> 30060 | G39: ='1re L'!H84 -> 8190 | H39: ='1re L'!H86 -> 0.20087884 | I39: ='1re L'!H87 -> Total incomplet : 1 prix de vente à fournir | J39: 2
A40: 1re L | B40: Confort | C40: =COUNTA('1re L'!C95:C131) -> 37 | D40: ='1re L'!H137 -> 12 | E40: ='1re L'!H133 -> 65615 | F40: ='1re L'!H134 -> 50600 | G40: ='1re L'!H136 -> 13440 | H40: ='1re L'!H138 -> 0.12192334 | I40: ='1re L'!H139 -> Total incomplet : 1 prix de vente à fournir | J40: 3
...

Sheet Manquants
A1: Priorité | B1: Article manquant | C1: Classes et gammes concernées | D1: Pourquoi | E1: Où chercher
A2: Haute | B2: Copies doubles (A-CREER-03), Calligraphe 192 p GF (A-CREER-01), Calligraphe 96 p GF (A-CREER-02) | C2: Collège, lycée, STEG | D2: Rattachés aux produits de l'app lors de l'intégration. Copies doubles : 1 300 / 1 800 | E2: Intégration
A3: Info | B3: Livres Korka Diallo | C3: Confort 3e, 2nde S, 1re S1 et S2, Tle L, S1 et S2 | D3: Faits le 26/09 avec le catalogue Korka (prix public). Pas de physique-chimie de Terminale S1 au bon prix (le Sakho est à 38 000 F), pas de SVT en Première et Terminale S2 pour ne pas doubler le manuel Didactikos | E3: —
A4: Haute | B4: Format exact du L'écolier 192 p (SAC-005) | C4: Essentiel collège, lycée, STEG | D4: S'il est en petit format, l'Essentiel n'a aucun grand format. Edushop vend un 192 p à 500 F en 17x22 | E4: Papex
A5: Haute | B5: Le Vieux Nègre et la Médaille (Oyono) | C5: Complet 5e | D5: Seule œuvre de 5e de ta liste absente | E5: LPD
A6: Haute | B6: Phèdre (Racine) | C6: Complet Seconde | D6: Dans 3 listes sur 4 | E6: LPD
A7: Haute | B7: La Tragédie du roi Christophe (Césaire) | C7: Complet Première | D7: Dans 2 listes et ta liste | E7: LPD
A8: Haute | B8: Les Soleils des Indépendances (Kourouma) | C8: Complet Terminale | D8: Dans les 4 listes de Terminale | E8: LPD
A9: Haute | B9: L'Exil d'Albouri (Ndao), Antigone (Anouilh) | C9: Complet Terminale | D9: Chacun dans 2 listes | E9: LPD
A10: Moyenne | B10: Kandia physique-chimie (Seconde S, Première S, Terminale S) | C10: Complet lycée S | D10: Demandé par les deux lycées | E10: LPD, Clairafrique
A11: Moyenne | B11: Le Français en 6e, en Seconde, en 1re et Terminale (Edicef) | C11: Complet 6e et lycée | D11: Demandés par toutes les écoles ; seuls 5e et 3e sont au catalogue | E11: LPD
A12: Moyenne | B12: Cahier de TP (grand format) | C12: Collège et lycée (HG, SVT) | D12: Sainte-Marie et ton exemple de 3e le demandent. Edushop le vend 1 000 à 2 000 F | E12: Papex, LPD
... A19: Info | B19: CIAM (maths lycée) | C19: Lycée | D19: Pas disponible chez tes fournisseurs : retiré. La Clé des Cracks sert de ressource en maths | E19: —

Sheet Exclus
A1: Article des listes | B1: Pourquoi il n'est pas dans les kits
A2: Mouchoirs, sous-main, étiquettes | B2: Pas du matériel scolaire à proprement parler
A3: Blouse de laboratoire, tenue d'EPS, baskets, maillot, lunettes de piscine | B3: Textile et sport : hors papeterie
A4: Clé USB 16 Go | B4: Utile mais hors catalogue et hors papeterie ; à proposer à part si un fournisseur en a
A5: Flûte à bec, cahier de musique | B5: Demandés seulement par les écoles privées ; à garder d'une année sur l'autre
A6: Gouaches, pinceaux, canson, feutres d'arts plastiques | B6: Arts plastiques souvent « à facturer » par l'école ; LPD a de quoi faire un pack à part
A7: Globe, planisphère, gabarit carte de France | B7: Matériel de classe ou très spécifique à une école
A8: Cahiers de latin, d'allemand, d'arabe, de catéchèse et d'éthique | B8: Options propres à certaines écoles : à proposer en ajout, pas dans le kit de base
A9: Fascicules et livres vendus par l'école (HG, espagnol, arabe, Cambridge, livres religieux) | B9: Vendus uniquement par l'établissement
A10: Protège-cahiers dans l'Essentiel et au primaire | B10: Depuis le 26/09, ils sont dans le Complet et le Confort du collège, du lycée et de la STEG (1 par cahier, 150 F). Pas dans l'Essentiel ni au primaire : la liste Dar El-Hadith ne les demande pas
A11: Trousse | B11: Utile, mais chaque trousse est un modèle différent, et les kits ne proposent pas de choix : à vendre à côté, comme le sac

Sheet Écarts Edushop
A1: ID SacAdo | B1: Notre article | C1: Notre PV (FCFA) | D1: Statut vente / achat | E1: Produit Edushop (n°) | F1: Prix Edushop (FCFA) | G1: Écart | H1: Verdict | I1: Comparable ?
A2: S053 | B2: =INDEX(Articles!$C$2:$C$148,MATCH(A2,Articles!$A$2:$A$148,0)) -> Éponge | C2: =INDEX(Articles!$G$2:$G$148,MATCH(A2,Articles!$A$2:$A$148,0)) -> 1500 | D2: =INDEX(Articles!$H$2:$H$148,MATCH(A2,Articles!$A$2:$A$148,0))&" / "&INDEX(Articles!$F$2:$F$148,MATCH(A2,Articles!$A$2:$A$148,0)) -> Fixé / Inconnu | E2: Éponge (69) | F2: 200 | G2: =(C2-F2)/F2 -> 6.5 | H2: =IF(G2>=0.5,"Nous : beaucoup plus cher",IF(G2<=-0.35,"Nous : beaucoup moins cher",IF(ABS(G2)>=0.25,"Écart moyen","Aligné"))) -> Nous : beaucoup plus cher | I2: Oui, même produit
A3: S109 | B3: =INDEX(Articles!$C$2:$C$148,MATCH(A3,Articles!$A$2:$A$148,0)) -> Protège-cahier couleur petit format (à l'unité) | C3: =INDEX(Articles!$G$2:$G$148,MATCH(A3,Articles!$A$2:$A$148,0)) -> 150 | D3: =INDEX(Articles!$H$2:$H$148,MATCH(A3,Articles!$A$2:$A$148,0))&" / "&INDEX(Articles!$F$2:$F$148,MATCH(A3,Articles!$A$2:$A$148,0)) -> Fixé / Inconnu | E3: Protège-cahier (107 à 112) | F3: 100 | G3: =(C3-F3)/F3 -> 0.5 | H3: =IF(G3>=0.5,"Nous : beaucoup plus cher",IF(G3<=-0.35,"Nous : beaucoup moins cher",IF(ABS(G3)>=0.25,"Écart moyen","Aligné"))) -> Nous : beaucoup plus cher | I3: Oui, même produit
A4: CIS-ardoise | B4: =INDEX(Articles!$C$2:$C$148,MATCH(A4,Articles!$A$2:$A$148,0)) -> Ardoise quadrillée avec poignée | C4: =INDEX(Articles!$G$2:$G$148,MATCH(A4,Articles!$A$2:$A$148,0)) -> 2500 | D4: =INDEX(Articles!$H$2:$H$148,MATCH(A4,Articles!$A$2:$A$148,0))&" / "&INDEX(Articles!$F$2:$F$148,MATCH(A4,Articles!$A$2:$A$148,0)) -> Fixé / Confirmé | E4: Ardoise effaçable MM quadrillée (52) | F4: 700 | G4: =(C4-F4)/F4 -> 2.5714286 | H4: =IF(G4>=0.5,"Nous : beaucoup plus cher",IF(G4<=-0.35,"Nous : beaucoup moins cher",IF(ABS(G4)>=0.25,"Écart moyen","Aligné"))) -> Nous : beaucoup plus cher | I4: Proche : la nôtre a une poignée
A5: S086 | B5: =INDEX(Articles!$C$2:$C$148,MATCH(A5,Articles!$A$2:$A$148,0)) -> Ardoise scolaire | C5: =INDEX(Articles!$G$2:$G$148,MATCH(A5,Articles!$A$2:$A$148,0)) -> 900 | D5: =INDEX(Articles!$H$2:$H$148,MATCH(A5,Articles!$A$2:$A$148,0))&" / "&INDEX(Articles!$F$2:$F$148,MATCH(A5,Articles!$A$2:$A$148,0)) -> Fixé / Estimé | E5: Ardoise (1) | F5: 500 | G5: =(C5-F5)/F5 -> 0.8 | H5: =IF(G5>=0.5,"Nous : beaucoup plus cher",IF(G5<=-0.35,"Nous : beaucoup moins cher",IF(ABS(G5)>=0.25,"Écart moyen","Aligné"))) -> Nous : beaucoup plus cher | I5: Oui
A6: LIT-013 | B6: =INDEX(Articles!$C$2:$C$148,MATCH(A6,Articles!$A$2:$A$148,0)) -> Sous l'orage (Seydou Badian) | C6: =INDEX(Articles!$G$2:$G$148,MATCH(A6,Articles!$A$2:$A$148,0)) -> 3500 | D6: =INDEX(Articles!$H$2:$H$148,MATCH(A6,Articles!$A$2:$A$148,0))&" / "&INDEX(Articles!$F$2:$F$148,MATCH(A6,Articles!$A$2:$A$148,0)) -> Fixé / Estimé | E6: Sous l'orage (95) | F6: 1800 | G6: =(C6-F6)/F6 -> 0.94444444 | H6: =IF(G6>=0.5,"Nous : beaucoup plus cher",IF(G6<=-0.35,"Nous : beaucoup moins cher",IF(ABS(G6)>=0.25,"Écart moyen","Aligné"))) -> Nous : beaucoup plus cher | I6: Oui : même titre. Nos autres romans africains à 3 500 F sont sans doute trop hauts aussi
A7: SAC-041 | B7: =INDEX(Articles!$C$2:$C$148,MATCH(A7,Articles!$A$2:$A$148,0)) -> Compas Maped | C7: =INDEX(Articles!$G$2:$G$148,MATCH(A7,Articles!$A$2:$A$148,0)) -> 2000 | D7: =INDEX(Articles!$H$2:$H$148,MATCH(A7,Articles!$A$2:$A$148,0))&" / "&INDEX(Articles!$F$2:$F$148,MATCH(A7,Articles!$A$2:$A$148,0)) -> Fixé / Confirmé | E7: Compas (81) | F7: 600 | G7: =(C7-F7)/F7 -> 2.3333333 | H7: =IF(G7>=0.5,"Nous : beaucoup plus cher",IF(G7<=-0.35,"Nous : beaucoup moins cher",IF(ABS(G7)>=0.25,"Écart moyen","Aligné"))) -> Nous : beaucoup plus cher | I7: Qualité différente : Maped chez nous
A8: SAC-069 | B8: =INDEX(Articles!$C$2:$C$148,MATCH(A8,Articles!$A$2:$A$148,0)) -> Correcteur souris ARK | C8: =INDEX(Articles!$G$2:$G$148,MATCH(A8,Articles!$A$2:$A$148,0)) -> 1000 | D8: =INDEX(Articles!$H$2:$H$148,MATCH(A8,Articles!$A$2:$A$148,0))&" / "&INDEX(Articles!$F$2:$F$148,MATCH(A8,Articles!$A$2:$A$148,0)) -> Fixé / Confirmé | E8: Blanco (119) | F8: 300 | G8: =(C8-F8)/F8 -> 2.3333333 | H8: =IF(G8>=0.5,"Nous : beaucoup plus cher",IF(G8<=-0.35,"Nous : beaucoup moins cher",IF(ABS(G8)>=0.25,"Écart moyen","Aligné"))) -> Nous : beaucoup plus cher | I8: Produit différent : souris chez nous, liquide chez eux
A9: S129 | B9: =INDEX(Articles!$C$2:$C$148,MATCH(A9,Articles!$A$2:$A$148,0)) -> Cahier de dessin TPG | C9: =INDEX(Articles!$G$2:$G$148,MATCH(A9,Articles!$A$2:$A$148,0)) -> 550 | D9: =INDEX(Articles!$H$2:$H$148,MATCH(A9,Articles!$A$2:$A$148,0))&" / "&INDEX(Articles!$F$2:$F$148,MATCH(A9,Articles!$A$2:$A$148,0)) -> Fixé / Inconnu | E9: Cahier dessin grand modèle (10) | F9: 450 | G9: =(C9-F9)/F9 -> 0.22222222 | H9: =IF(G9>=0.5,"Nous : beaucoup plus cher",IF(G9<=-0.35,"Nous : beaucoup moins cher",IF(ABS(G9)>=0.25,"Écart moyen","Aligné"))) -> Aligné | I9: Proche
A10: S009 | B10: =INDEX(Articles!$C$2:$C$148,MATCH(A10,Articles!$A$2:$A$148,0)) -> Gomme Staedtler Mars Plastic | C10: =INDEX(Articles!$G$2:$G$148,MATCH(A10,Articles!$A$2:$A$148,0)) -> 250 | D10: =INDEX(Articles!$H$2:$H$148,MATCH(A10,Articles!$A$2:$A$148,0))&" / "&INDEX(Articles!$F$2:$F$148,MATCH(A10,Articles!$A$2:$A$148,0)) -> Fixé / Estimé | E10: Gomme (122) | F10: 100 | G10: =(C10-F10)/F10 -> 1.5 | H10: =IF(G10>=0.5,"Nous : beaucoup plus cher",IF(G10<=-0.35,"Nous : beaucoup moins cher",IF(ABS(G10)>=0.25,"Écart moyen","Aligné"))) -> Nous : beaucoup plus cher | I10: Qualité différente : Staedtler chez nous
A11: SAC-017 | B11: =INDEX(Articles!$C$2:$C$148,MATCH(A11,Articles!$A$2:$A$148,0)) -> Taille-crayon avec réservoir Maped | C11: =INDEX(Articles!$G$2:$G$148,MATCH(A11,Articles!$A$2:$A$148,0)) -> 500 | D11: =INDEX(Articles!$H$2:$H$148,MATCH(A11,Articles!$A$2:$A$148,0))&" / "&INDEX(Articles!$F$2:$F$148,MATCH(A11,Articles!$A$2:$A$148,0)) -> Estimé / Estimé | E11: Taille-crayon (126) | F11: 200 | G11: =(C11-F11)/F11 -> 1.5 | H11: =IF(G11>=0.5,"Nous : beaucoup plus cher",IF(G11<=-0.35,"Nous : beaucoup moins cher",IF(ABS(G11)>=0.25,"Écart moyen","Aligné"))) -> Nous : beaucoup plus cher | I11: Qualité différente : réservoir Maped chez nous
A12: S069 | B12: =INDEX(Articles!$C$2:$C$148,MATCH(A12,Articles!$A$2:$A$148,0)) -> Règle métal 30 cm | C12: =INDEX(Articles!$G$2:$G$148,MATCH(A12,Articles!$A$2:$A$148,0)) -> 550 | D12: =INDEX(Articles!$H$2:$H$148,MATCH(A12,Articles!$A$2:$A$148,0))&" / "&INDEX(Articles!$F$2:$F$148,MATCH(A12,Articles!$A$2:$A$148,0)) -> Fixé / Estimé | E12: Règle 30 cm (84) | F12: 300 | G12: =(C12-F12)/F12 -> 0.83333333 | H12: =IF(G12>=0.5,"Nous : beaucoup plus cher",IF(G12<=-0.35,"Nous : beaucoup moins cher",IF(ABS(G12)>=0.25,"Écart moyen","Aligné"))) -> Nous : beaucoup plus cher | I12: Proche : métal chez nous
A13: SAC-016 | B13: =INDEX(Articles!$C$2:$C$148,MATCH(A13,Articles!$A$2:$A$148,0)) -> Ciseaux Maped 13 cm Security | C13: =INDEX(Articles!$G$2:$G$148,MATCH(A13,Articles!$A$2:$A$148,0)) -> 900 | D13: =INDEX(Articles!$H$2:$H$148,MATCH(A13,Articles!$A$2:$A$148,0))&" / "&INDEX(Articles!$F$2:$F$148,MATCH(A13,Articles!$A$2:$A$148,0)) -> Estimé / Estimé | E13: Ciseaux bouts ronds 13 cm (65) | F13: 500 | G13: =(C13-F13)/F13 -> 0.8 | H13: =IF(G13>=0.5,"Nous : beaucoup plus cher",IF(G13<=-0.35,"Nous : beaucoup moins cher",IF(ABS(G13)>=0.25,"Écart moyen","Aligné"))) -> Nous : beaucoup plus cher | I13: Oui, même taille ; Maped chez nous
... A42: S020 | B42: =INDEX(Articles!$C$2:$C$148,MATCH(A42,Articles!$A$2:$A$148,0)) -> Sac à dos bleu marine | C42: =INDEX(Articles!$G$2:$G$148,MATCH(A42,Articles!$A$2:$A$148,0)) -> 7000 | D42: =INDEX(Articles!$H$2:$H$148,MATCH(A42,Articles!$A$2:$A$148,0))&" / "&INDEX(Articles!$F$2:$F$148,MATCH(A42,Articles!$A$2:$A$148,0)) -> Fixé / Confirmé | E42: Sac à dos enfant (113) | F42: 10000 | G42: =(C42-F42)/F42 -> -0.3 | H42: =IF(G42>=0.5,"Nous : beaucoup plus cher",IF(G42<=-0.35,"Nous : beaucoup moins cher",IF(ABS(G42)>=0.25,"Écart moyen","Aligné"))) -> Écart moyen | I42: Proche
A44: Source : fichier produits Edushop envoyé par SacAdo le 25/09/2026. Prix Edushop en bleu. Les produits Edushop sont souvent sans marque : un écart peut venir de la qualité (Maped, Calligraphe, Staedtler chez nous).
A45: Hors kits mais au catalogue : Horizontes (espagnol) 3 550 F chez nous contre 2 500 à 3 000 F chez Edushop ; English for Success 4 000 F contre 3 000 F.
A46: Tous les packs Edushop sont affichés à 20 000 F, du CP à la Terminale, sans contenu détaillé : ce prix ne sert pas de repère.

Sheet Œuvres
A1: Classe | B1: Titre | C1: Cité par | D1: Place dans les kits | E1: Au catalogue ?
A2: 6e | B2: Le Pagne noir | C2: Ta liste, ISJA (et Sainte-Marie en 5e) | D2: Complet | E2: Oui (LIT-014)
A3: 6e | B3: Les Contes d'Amadou Koumba | C3: Ta liste (Sainte-Marie : Les Nouveaux Contes) | D3: Confort | E3: Oui (LIT-011)
A4: 6e | B4: Fables de La Fontaine | C4: Ta liste | D4: Confort | E4: Non
A5: 6e | B5: Les Fourberies de Scapin / Le Médecin malgré lui | C5: ISJA / Sainte-Marie | D5: Confort | E5: Non
A6: 5e | B6: La Belle Histoire de Leuk-le-Lièvre | C6: Ta liste | D6: Complet | E6: Oui (LIT-021)
A7: 5e | B7: Le Vieux Nègre et la Médaille | C7: Ta liste | D7: Complet | E7: Non
A8: 5e | B8: L'Os de Mor Lam | C8: Sainte-Marie | D8: Confort | E8: Oui (LIT-023), photo à refaire
A9: 5e | B9: Le Malade imaginaire | C9: ISJA | D9: Confort | E9: Oui (LIT-018)
A10: 5e | B10: Maïmouna | C10: ISJA | D10: Non retenu | E10: Oui (LIT-012)
A11: 4e | B11: Sous l'orage | C11: Ta liste, Sainte-Marie, ISJA | D11: Complet | E11: Oui (LIT-013)
A12: 4e | B12: Eugénie Grandet | C12: ISJA | D12: Confort | E12: Oui (NIO-2900)
... A37: Terminale | B37: L'Aventure ambiguë | C37: Ta liste | D37: Confort | E37: Oui (LIT-002)

Sheet Articles
A1: ID | B1: Fournisseur | C1: Désignation | D1: Unité de vente | E1: Prix achat (FCFA) | F1: Statut achat | G1: Prix vente (FCFA) | H1: Statut vente | I1: Remarque
A2: SAC-001 | B2: Papex | C2: Cahier de dessin L'écolier 32 pages | D2: pièce | E2: 150 | F2: Confirmé | G2: 250 | H2: Fixé
A3: SAC-004 | B3: Papex | C3: Cahier L'écolier 48 pages | D3: pièce | E3: 175 | F3: Confirmé | G3: 275 | H3: Estimé
A4: SAC-005 | B4: Papex | C4: Cahier L'écolier 192 pages | D4: pièce | E4: 400 | F4: Confirmé | G4: 500 | H4: Estimé | I4: Format (17x22 ou 24x32) non précisé : à confirmer
A5: SAC-048 | B5: Papex | C5: Cahier Calligraphe 96 pages 17x22 56 g seyès | D5: pièce | E5: 350 | F5: Confirmé | G5: 450 | H5: Fixé
A6: SAC-033 | B6: Papex | C6: Cahier Calligraphe 140 pages 17x22 90 g seyès | D6: pièce | E6: 650 | F6: Estimé | G6: 750 | H6: Fixé | I6: Achat interpolé
A7: SAC-046 | B7: Papex | C7: Cahier Calligraphe 192 pages 17x22 90 g seyès | D7: pièce | E7: 800 | F7: Confirmé | G7: 900 | H7: Fixé
A8: SAC-036 | B8: Papex | C8: Cahier Calligraphe 140 pages 24x32 90 g seyès | D8: pièce | E8: 1250 | F8: Estimé | G8: 1500 | H8: Fixé | I8: Achat interpolé
A9: A-CREER-01 | B9: Papex | C9: Cahier Calligraphe 192 pages 24x32 (grand format) | D9: pièce | E9: 1500 | F9: Confirmé | G9: 1650 | H9: Fixé | I9: Présent dans l'app selon toi : remplacer cet ID par celui de l'app et vérifier le prix (tarif Papex GF 192 p 1 500 / 1 650)
A10: A-CREER-02 | B10: Papex | C10: Cahier Calligraphe 96 pages 24x32 (grand format) | D10: pièce | E10: 1000 | F10: Confirmé | G10: 1350 | H10: Fixé | I10: Présent dans l'app selon toi : remplacer cet ID par celui de l'app et vérifier le prix (tarif Papex GF 96 p 1 000 / 1 350)
A11: A-CREER-03 | B11: À préciser | C11: Paquet de copies doubles grand format | D11: paquet | E11: 1300 | F11: Confirmé | G11: 1800 | H11: Fixé | I11: Prix donnés par SacAdo le 25/09/2026 (achat 1 300, vente 1 800)
A12: CDC-3M | B12: Korka Diallo | C12: MATHEMATIQUES TROISIEME (Korka Diallo, Le BFEM en poche) | D12: pièce | E12: 8000 | F12: Confirmé | G12: 10000 | H12: Fixé | I12: Catalogue Korka : prix public = prix de vente, achat -20 %
A13: CDC-3PC | B13: Korka Diallo | C13: PHYSIQUE CHIMIE TROISIEME (Korka Diallo, Le BFEM en poche) | D13: pièce | E13: 4000 | F13: Confirmé | G13: 5000 | H13: Fixé | I13: Catalogue Korka
A14: CDC-3ANG | B14: Korka Diallo | C14: ANNALE D'ANGLAIS TROISIEME (Korka Diallo, Club de l'Excellence) | D14: pièce | E14: 2400 | F14: Confirmé | G14: 3000 | H14: Fixé | I14: Catalogue Korka. Annales pour le BFEM
A15: CDC-2M | B15: Korka Diallo | C15: KAAMILE DE MATHS - SECONDE S (Korka Diallo, Collection Cracks) | D15: pièce | E15: 8000 | F15: Confirmé | G15: 10000 | H15: Fixé | I15: Catalogue Korka
A16: CDC-2PC | B16: Korka Diallo | C16: PHYSIQUE CHIMIE SECONDE S (Korka Diallo, Collection Cracks) | D16: pièce | E16: 8000 | F16: Confirmé | G16: 10000 | H16: Fixé | I16: Catalogue Korka
A17: CDC-2SVT | B17: Korka Diallo | C17: SVT SECONDE S | D17: pièce | E17: 12000 | F17: Confirmé | G17: 15000 | H17: Fixé | I17: Catalogue Korka. Auteur non indiqué
A18: CDC-1M-S1 | B18: Korka Diallo | C18: MATHS 1S1 (CRACKS EN MATHS) (Korka Diallo) | D18: pièce | E18: 12000 | F18: Confirmé | G18: 15000 | H18: Fixé | I18: Catalogue Korka. Édition S1
A19: CDC-1M-S2 | B19: Korka Diallo | C19: MATHS 1S2 - LA CLE DES CRACKS (Korka Diallo) | D19: pièce | E19: 4800 | F19: Confirmé | G19: 6000 | H19: Fixé | I19: Catalogue Korka. Édition S2
... A24: CDC-TPHILO | B24: Korka Diallo | C24: PHILOSOPHIE TERMINALES L ET S - L'ESSENTIEL (Korka Diallo, Club de l'Excellence) | D24: pièce | E24: 2400 | F24: Confirmé | G24: 3000 | H24: Fixé | I24: Catalogue Korka
A25: S109 | B25: LPD | C25: Protège-cahier couleur petit format (à l'unité) | D25: pièce | F25: Inconnu | G25: 150 | H25: Fixé | I25: PV corrigé par SacAdo le 26/09 (950 -> 150). Format supposé petit : à confirmer
A26: A-CREER-04 | B26: À préciser | C26: Protège-cahier grand format (à l'unité) | D26: pièce | F26: Inconnu | H26: À fournir | I26: À trouver dans l'app. Sans ce produit, les cahiers grand format des kits n'ont pas de protège-cahier
A27: SAC-007 | B27: Papex | C27: Kit de traçage 30 cm, 4 pièces L'écolier | D27: pièce | E27: 650 | F27: Confirmé | G27: 900 | H27: Estimé
A28: SAC-019 | B28: Papex | C28: Crayons de couleur Maped, boîte de 12 | D28: boîte | E28: 650 | F28: Estimé | G28: 900 | H28: Estimé
A29: SAC-024 | B29: Papex | C29: Crayons de couleur Maped Nightfall, boîte de 24 | D29: boîte | E29: 1300 | F29: Estimé | G29: 1600 | H29: Estimé
A30: SAC-065 | B30: Papex | C30: Stylo à bille Schneider Tops 505 M bleu | D30: pièce | F30: Inconnu | G30: 100 | H30: Fixé | I30: Achat supposé 50 à 80 F
A31: SAC-104 | B31: Papex | C31: Stylo à bille Schneider Tops 505 M vert | D31: pièce | F31: Inconnu | G31: 100 | H31: Fixé | I31: Achat supposé 50 à 80 F
A32: SAC-066 | B32: Papex | C32: Pack de 4 stylos Schneider Tops 505 M (bleu, noir, rouge, vert) | D32: pack de 4 | F32: Inconnu | G32: 400 | H32: Fixé | I32: Achat supposé 200 à 320 F
A33: SAC-062 | B33: Papex | C33: Stylo 4 couleurs Schneider | D33: pièce | E33: 1500 | F33: Confirmé | G33: 1750 | H33: Fixé
A34: SAC-017 | B34: Papex | C34: Taille-crayon avec réservoir Maped | D34: pièce | E34: 350 | F34: Estimé | G34: 500 | H34: Estimé
A35: SAC-031 | B35: Papex | C35: Bâton de colle Giotto 10 g | D35: pièce | E35: 350 | F35: Estimé | G35: 500 | H35: Estimé | I35: Achat en fourchette 300 à 400 F
A36: SAC-034 | B36: Papex | C36: Bâton de colle Giotto 20 g | D36: pièce | E36: 650 | F36: Estimé | G36: 900 | H36: Estimé | I36: Achat en fourchette 600 à 700 F
A37: SAC-016 | B37: Papex | C37: Ciseaux Maped 13 cm Security | D37: pièce | E37: 650 | F37: Estimé | G37: 900 | H37: Estimé
A38: SAC-041 | B38: Papex | C38: Compas Maped | D38: pièce | E38: 1750 | F38: Confirmé | G38: 2000 | H38: Fixé
A39: SAC-037 | B39: Papex | C39: Surligneurs Maped Fluo Peps, pochette de 4 | D39: pochette | E39: 2000 | F39: Confirmé | G39: 2500 | H39: Estimé
A40: SAC-069 | B40: Papex | C40: Correcteur souris ARK | D40: pièce | E40: 700 | F40: Confirmé | G40: 1000 | H40: Fixé
A41: SAC-055 | B41: Papex | C41: Chemise 3 rabats à élastique | D41: pièce | F41: Inconnu | G41: 500 | H41: Estimé | I41: PV calé sur le prix public Chez Monami, pas de prix fournisseur
A42: SAC-022 | B42: Papex | C42: Calculatrice Casio fx-92 Collège | D42: pièce | E42: 7000 | F42: Confirmé | G42: 8000 | H42: Fixé | I42: PV corrigé par SacAdo le 26/09 (9 000 -> 8 000)
A43: SAC-112 | B43: Papex | C43: Dictionnaire Le Robert de français, 65 000 mots | D43: pièce | E43: 3000 | F43: Confirmé | G43: 3500 | H43: Fixé
A44: S011 | B44: LPD | C44: Règle plastique transparente 20 cm | D44: pièce | F44: Inconnu | G44: 100 | H44: Fixé | I44: PV corrigé par SacAdo le 26/09 (300 -> 100). Achat à obtenir
...

Sheet CI
A1: Kit CI
A2: Liste réelle du Complexe Dar El-Hadith. Contrôle croisé avec la liste ISJA 2026-2027 (plus chargée, écoles privées).
A4: CI — Essentiel
A5: Groupe (app) | B5: Besoin (liste) | C5: ID | D5: Désignation | E5: Fournisseur | F5: Qté | G5: PV unit. (FCFA) | H5: Sous-total vente | I5: PA unit. (FCFA) | J5: Sous-total achat | K5: Statut vente | L5: Statut achat | M5: Remarque | N5: Coché par défaut
A6: Cahiers | B6: Cahier 32 pages | C6: SAC-004 | D6: =INDEX(Articles!$C$2:$C$148,MATCH(C6,Articles!$A$2:$A$148,0)) -> Cahier L'écolier 48 pages | E6: =INDEX(Articles!$B$2:$B$148,MATCH(C6,Articles!$A$2:$A$148,0)) -> Papex | F6: 2 | G6: =IF(INDEX(Articles!$G$2:$G$148,MATCH(C6,Articles!$A$2:$A$148,0))="","",INDEX(Articles!$G$2:$G$148,MATCH(C6,Articles!$A$2:$A$148,0))) -> 275 | H6: =IF(G6="",0,F6*G6) -> 550 | I6: =IF(INDEX(Articles!$E$2:$E$148,MATCH(C6,Articles!$A$2:$A$148,0))="","",INDEX(Articles!$E$2:$E$148,MATCH(C6,Articles!$A$2:$A$148,0))) -> 175 | J6: =IF(I6="","",F6*I6) -> 350 | K6: =INDEX(Articles!$H$2:$H$148,MATCH(C6,Articles!$A$2:$A$148,0)) -> Estimé | L6: =INDEX(Articles!$F$2:$F$148,MATCH(C6,Articles!$A$2:$A$148,0)) -> Confirmé | M6: 48 p (32 p absent) | N6: Oui
A7: Ardoise | B7: Ardoise | C7: S086 | D7: =INDEX(Articles!$C$2:$C$148,MATCH(C7,Articles!$A$2:$A$148,0)) -> Ardoise scolaire | E7: =INDEX(Articles!$B$2:$B$148,MATCH(C7,Articles!$A$2:$A$148,0)) -> LPD | F7: 1 | G7: =IF(INDEX(Articles!$G$2:$G$148,MATCH(C7,Articles!$A$2:$A$148,0))="","",INDEX(Articles!$G$2:$G$148,MATCH(C7,Articles!$A$2:$A$148,0))) -> 900 | H7: =IF(G7="",0,F7*G7) -> 900 | I7: =IF(INDEX(Articles!$E$2:$E$148,MATCH(C7,Articles!$A$2:$A$148,0))="","",INDEX(Articles!$E$2:$E$148,MATCH(C7,Articles!$A$2:$A$148,0))) -> 600 | J7: =IF(I7="","",F7*I7) -> 600 | K7: =INDEX(Articles!$H$2:$H$148,MATCH(C7,Articles!$A$2:$A$148,0)) -> Fixé | L7: =INDEX(Articles!$F$2:$F$148,MATCH(C7,Articles!$A$2:$A$148,0)) -> Estimé | N7: Oui
A8: Petit matériel | B8: Éponge | C8: S053 | D8: =INDEX(Articles!$C$2:$C$148,MATCH(C8,Articles!$A$2:$A$148,0)) -> Éponge | E8: =INDEX(Articles!$B$2:$B$148,MATCH(C8,Articles!$A$2:$A$148,0)) -> LPD | F8: 1 | G8: =IF(INDEX(Articles!$G$2:$G$148,MATCH(C8,Articles!$A$2:$A$148,0))="","",INDEX(Articles!$G$2:$G$148,MATCH(C8,Articles!$A$2:$A$148,0))) -> 1500 | H8: =IF(G8="",0,F8*G8) -> 1500 | I8: =IF(INDEX(Articles!$E$2:$E$148,MATCH(C8,Articles!$A$2:$A$148,0))="","",INDEX(Articles!$E$2:$E$148,MATCH(C8,Articles!$A$2:$A$148,0))) | J8: =IF(I8="","",F8*I8) | K8: =INDEX(Articles!$H$2:$H$148,MATCH(C8,Articles!$A$2:$A$148,0)) -> Fixé | L8: =INDEX(Articles!$F$2:$F$148,MATCH(C8,Articles!$A$2:$A$148,0)) -> Inconnu | N8: Oui
A9: Géométrie | B9: Règle | C9: S011 | D9: =INDEX(Articles!$C$2:$C$148,MATCH(C9,Articles!$A$2:$A$148,0)) -> Règle plastique transparente 20 cm | E9: =INDEX(Articles!$B$2:$B$148,MATCH(C9,Articles!$A$2:$A$148,0)) -> LPD | F9: 1 | G9: =IF(INDEX(Articles!$G$2:$G$148,MATCH(C9,Articles!$A$2:$A$148,0))="","",INDEX(Articles!$G$2:$G$148,MATCH(C9,Articles!$A$2:$A$148,0))) -> 100 | H9: =IF(G9="",0,F9*G9) -> 100 | I9: =IF(INDEX(Articles!$E$2:$E$148,MATCH(C9,Articles!$A$2:$A$148,0))="","",INDEX(Articles!$E$2:$E$148,MATCH(C9,Articles!$A$2:$A$148,0))) | J9: =IF(I9="","",F9*I9) | K9: =INDEX(Articles!$H$2:$H$148,MATCH(C9,Articles!$A$2:$A$148,0)) -> Fixé | L9: =INDEX(Articles!$F$2:$F$148,MATCH(C9,Articles!$A$2:$A$148,0)) -> Inconnu | N9: Oui
A10: Écriture | B10: Crayon noir | C10: S065 | D10: =INDEX(Articles!$C$2:$C$148,MATCH(C10,Articles!$A$2:$A$148,0)) -> Crayon papier (vendu à l'unité) | E10: =INDEX(Articles!$B$2:$B$148,MATCH(C10,Articles!$A$2:$A$148,0)) -> LPD | F10: 1 | G10: =IF(INDEX(Articles!$G$2:$G$148,MATCH(C10,Articles!$A$2:$A$148,0))="","",INDEX(Articles!$G$2:$G$148,MATCH(C10,Articles!$A$2:$A$148,0))) -> 75 | H10: =IF(G10="",0,F10*G10) -> 75 | I10: =IF(INDEX(Articles!$E$2:$E$148,MATCH(C10,Articles!$A$2:$A$148,0))="","",INDEX(Articles!$E$2:$E$148,MATCH(C10,Articles!$A$2:$A$148,0))) | J10: =IF(I10="","",F10*I10) | K10: =INDEX(Articles!$H$2:$H$148,MATCH(C10,Articles!$A$2:$A$148,0)) -> Fixé | L10: =INDEX(Articles!$F$2:$F$148,MATCH(C10,Articles!$A$2:$A$148,0)) -> Inconnu | N10: Oui
A11: Écriture | B11: Bic bleu | C11: SAC-065 | D11: =INDEX(Articles!$C$2:$C$148,MATCH(C11,Articles!$A$2:$A$148,0)) -> Stylo à bille Schneider Tops 505 M bleu | E11: =INDEX(Articles!$B$2:$B$148,MATCH(C11,Articles!$A$2:$A$148,0)) -> Papex | F11: 2 | G11: =IF(INDEX(Articles!$G$2:$G$148,MATCH(C11,Articles!$A$2:$A$148,0))="","",INDEX(Articles!$G$2:$G$148,MATCH(C11,Articles!$A$2:$A$148,0))) -> 100 | H11: =IF(G11="",0,F11*G11) -> 200 | I11: =IF(INDEX(Articles!$E$2:$E$148,MATCH(C11,Articles!$A$2:$A$148,0))="","",INDEX(Articles!$E$2:$E$148,MATCH(C11,Articles!$A$2:$A$148,0))) | J11: =IF(I11="","",F11*I11) | K11: =INDEX(Articles!$H$2:$H$148,MATCH(C11,Articles!$A$2:$A$148,0)) -> Fixé | L11: =INDEX(Articles!$F$2:$F$148,MATCH(C11,Articles!$A$2:$A$148,0)) -> Inconnu | N11: Oui
A12: Art & dessin | B12: Paquet de crayons de couleur | C12: SAC-019 | D12: =INDEX(Articles!$C$2:$C$148,MATCH(C12,Articles!$A$2:$A$148,0)) -> Crayons de couleur Maped, boîte de 12 | E12: =INDEX(Articles!$B$2:$B$148,MATCH(C12,Articles!$A$2:$A$148,0)) -> Papex | F12: 1 | G12: =IF(INDEX(Articles!$G$2:$G$148,MATCH(C12,Articles!$A$2:$A$148,0))="","",INDEX(Articles!$G$2:$G$148,MATCH(C12,Articles!$A$2:$A$148,0))) -> 900 | H12: =IF(G12="",0,F12*G12) -> 900 | I12: =IF(INDEX(Articles!$E$2:$E$148,MATCH(C12,Articles!$A$2:$A$148,0))="","",INDEX(Articles!$E$2:$E$148,MATCH(C12,Articles!$A$2:$A$148,0))) -> 650 | J12: =IF(I12="","",F12*I12) -> 650 | K12: =INDEX(Articles!$H$2:$H$148,MATCH(C12,Articles!$A$2:$A$148,0)) -> Estimé | L12: =INDEX(Articles!$F$2:$F$148,MATCH(C12,Articles!$A$2:$A$148,0)) -> Estimé | N12: Oui
D13: Lignes sans prix de vente (à fournir) | H13: =COUNTIF(G6:G12,"") -> 0
D14: Total vente du kit (FCFA) | H14: =SUM(H6:H12) -> 4225
D15: Coût de revient connu (FCFA) | H15: =SUM(J6:J12) -> 1600
D16: Lignes sans prix d'achat | H16: =COUNTIF(I6:I12,"") -> 4
D17: Marge sur les lignes au coût connu (FCFA) | H17: =SUMPRODUCT((I6:I12<>"")*H6:H12)-H15 -> 750
D18: Nombre de cahiers (ligne « X cahiers » dans l'app) | H18: =SUMIF(A6:A12,"Cahiers",F6:F12) -> 2
D19: Part du prix de vente reposant sur des PV estimés | H19: =IF(H14=0,0,SUMIF(K6:K12,"<>Fixé",H6:H12)/H14) -> 0.34319527
D20: Statut du coût | H20: =IF(H13>0,"Total incomplet : "&H13&" prix de vente à fournir",IF(H16>0,"Coût incomplet : "&H16&" ligne(s) sans prix d'achat","Complet")) -> Coût incomplet : 4 ligne(s) sans prix d'achat
D22: Proposés décochés : livres du Complet (non comptés, cochables par le client)
A23: Manuels au programme | B23: Didactikos Langue et communication | C23: DID-6913 | D23: =INDEX(Articles!$C$2:$C$148,MATCH(C23,Articles!$A$2:$A$148,0)) -> Langue et communication C.I. | G23: =INDEX(Articles!$G$2:$G$148,MATCH(C23,Articles!$A$2:$A$148,0)) -> 3890 | N23: Non
A24: Manuels au programme | B24: Didactikos Mathématiques | C24: DID-6936 | D24: =INDEX(Articles!$C$2:$C$148,MATCH(C24,Articles!$A$2:$A$148,0)) -> Mathématiques C.I. | G24: =INDEX(Articles!$G$2:$G$148,MATCH(C24,Articles!$A$2:$A$148,0)) -> 3890 | N24: Non
A25: Manuels au programme | B25: Didactikos Découverte du monde | C25: DID-6949 | D25: =INDEX(Articles!$C$2:$C$148,MATCH(C25,Articles!$A$2:$A$148,0)) -> Découverte du monde C.I. | G25: =INDEX(Articles!$G$2:$G$148,MATCH(C25,Articles!$A$2:$A$148,0)) -> 3890 | N25: Non
D26: Total si tous les livres sont cochés (FCFA) | H26: =H14+SUM(G23:G25) -> 15895
D27: Option décochée par défaut, non comptée : | E27: =INDEX(Articles!$C$2:$C$148,MATCH("S027",Articles!$A$2:$A$148,0)) -> Cartable rigide bleu marine | H27: =INDEX(Articles!$G$2:$G$148,MATCH("S027",Articles!$A$2:$A$148,0)) -> 7500
D28: Manquants : | E28: Cahier double ligne (1)
A31: CI — Complet
A32: Groupe (app) | B32: Besoin (liste) | C32: ID | D32: Désignation | E32: Fournisseur | F32: Qté | G32: PV unit. (FCFA) | H32: Sous-total vente | I32: PA unit. (FCFA) | J32: Sous-total achat | K32: Statut vente | L32: Statut achat | M32: Remarque | N32: Coché par défaut
A33: Cahiers | B33: Cahier 32 pages | C33: SAC-048 | D33: =INDEX(Articles!$C$2:$C$148,MATCH(C33,Articles!$A$2:$A$148,0)) -> Cahier Calligraphe 96 pages 17x22 56 g seyès | E33: =INDEX(Articles!$B$2:$B$148,MATCH(C33,Articles!$A$2:$A$148,0)) -> Papex | F33: 2 | G33: =IF(INDEX(Articles!$G$2:$G$148,MATCH(C33,Articles!$A$2:$A$148,0))="","",INDEX(Articles!$G$2:$G$148,MATCH(C33,Articles!$A$2:$A$148,0))) -> 450 | H33: =IF(G33="",0,F33*G33) -> 900 | I33: =IF(INDEX(Articles!$E$2:$E$148,MATCH(C33,Articles!$A$2:$A$148,0))="","",INDEX(Articles!$E$2:$E$148,MATCH(C33,Articles!$A$2:$A$148,0))) -> 350 | J33: =IF(I33="","",F33*I33) -> 700 | K33: =INDEX(Articles!$H$2:$H$148,MATCH(C33,Articles!$A$2:$A$148,0)) -> Fixé | L33: =INDEX(Articles!$F$2:$F$148,MATCH(C33,Articles!$A$2:$A$148,0)) -> Confirmé | M33: 96 p Calligraphe (32 p absent) | N33: Oui
A34: Ardoise | B34: Ardoise | C34: CIS-ardoise | D34: =INDEX(Articles!$C$2:$C$148,MATCH(C34,Articles!$A$2:$A$148,0)) -> Ardoise quadrillée avec poignée | E34: =INDEX(Articles!$B$2:$B$148,MATCH(C34,Articles!$A$2:$A$148,0)) -> Cissé & Frères | F34: 1 | G34: =IF(INDEX(Articles!$G$2:$G$148,MATCH(C34,Articles!$A$2:$A$148,0))="","",INDEX(Articles!$G$2:$G$148,MATCH(C34,Articles!$A$2:$A$148,0))) -> 2500 | H34: =IF(G34="",0,F34*G34) -> 2500 | I34: =IF(INDEX(Articles!$E$2:$E$148,MATCH(C34,Articles!$A$2:$A$148,0))="","",INDEX(Articles!$E$2:$E$148,MATCH(C34,Articles!$A$2:$A$148,0))) -> 1500 | J34: =IF(I34="","",F34*I34) -> 1500 | K34: =INDEX(Articles!$H$2:$H$148,MATCH(C34,Articles!$A$2:$A$148,0)) -> Fixé | L34: =INDEX(Articles!$F$2:$F$148,MATCH(C34,Articles!$A$2:$A$148,0)) -> Confirmé | N34: Oui
A35: Petit matériel | B35: Éponge | C35: S053 | D35: =INDEX(Articles!$C$2:$C$148,MATCH(C35,Articles!$A$2:$A$148,0)) -> Éponge | E35: =INDEX(Articles!$B$2:$B$148,MATCH(C35,Articles!$A$2:$A$148,0)) -> LPD | F35: 1 | G35: =IF(INDEX(Articles!$G$2:$G$148,MATCH(C35,Articles!$A$2:$A$148,0))="","",INDEX(Articles!$G$2:$G$148,MATCH(C35,Articles!$A$2:$A$148,0))) -> 1500 | H35: =IF(G35="",0,F35*G35) -> 1500 | I35: =IF(INDEX(Articles!$E$2:$E$148,MATCH(C35,Articles!$A$2:$A$148,0))="","",INDEX(Articles!$E$2:$E$148,MATCH(C35,Articles!$A$2:$A$148,0))) | J35: =IF(I35="","",F35*I35) | K35: =INDEX(Articles!$H$2:$H$148,MATCH(C35,Articles!$A$2:$A$148,0)) -> Fixé | L35: =INDEX(Articles!$F$2:$F$148,MATCH(C35,Articles!$A$2:$A$148,0)) -> Inconnu | N35: Oui
A36: Géométrie | B36: Règle | C36: S069 | D36: =INDEX(Articles!$C$2:$C$148,MATCH(C36,Articles!$A$2:$A$148,0)) -> Règle métal 30 cm | E36: =INDEX(Articles!$B$2:$B$148,MATCH(C36,Articles!$A$2:$A$148,0)) -> LPD | F36: 1 | G36: =IF(INDEX(Articles!$G$2:$G$148,MATCH(C36,Articles!$A$2:$A$148,0))="","",INDEX(Articles!$G$2:$G$148,MATCH(C36,Articles!$A$2:$A$148,0))) -> 550 | H36: =IF(G36="",0,F36*G36) -> 550 | I36: =IF(INDEX(Articles!$E$2:$E$148,MATCH(C36,Articles!$A$2:$A$148,0))="","",INDEX(Articles!$E$2:$E$148,MATCH(C36,Articles!$A$2:$A$148,0))) -> 400 | J36: =IF(I36="","",F36*I36) -> 400 | K36: =INDEX(Articles!$H$2:$H$148,MATCH(C36,Articles!$A$2:$A$148,0)) -> Fixé | L36: =INDEX(Articles!$F$2:$F$148,MATCH(C36,Articles!$A$2:$A$148,0)) -> Estimé | N36: Oui
A37: Écriture | B37: Crayon noir | C37: S065 | D37: =INDEX(Articles!$C$2:$C$148,MATCH(C37,Articles!$A$2:$A$148,0)) -> Crayon papier (vendu à l'unité) | E37: =INDEX(Articles!$B$2:$B$148,MATCH(C37,Articles!$A$2:$A$148,0)) -> LPD | F37: 1 | G37: =IF(INDEX(Articles!$G$2:$G$148,MATCH(C37,Articles!$A$2:$A$148,0))="","",INDEX(Articles!$G$2:$G$148,MATCH(C37,Articles!$A$2:$A$148,0))) -> 75 | H37: =IF(G37="",0,F37*G37) -> 75 | I37: =IF(INDEX(Articles!$E$2:$E$148,MATCH(C37,Articles!$A$2:$A$148,0))="","",INDEX(Articles!$E$2:$E$148,MATCH(C37,Articles!$A$2:$A$148,0))) | J37: =IF(I37="","",F37*I37) | K37: =INDEX(Articles!$H$2:$H$148,MATCH(C37,Articles!$A$2:$A$148,0)) -> Fixé | L37: =INDEX(Articles!$F$2:$F$148,MATCH(C37,Articles!$A$2:$A$148,0)) -> Inconnu | N37: Oui
A38: Écriture | B38: Bic bleu | C38: SAC-065 | D38: =INDEX(Articles!$C$2:$C$148,MATCH(C38,Articles!$A$2:$A$148,0)) -> Stylo à bille Schneider Tops 505 M bleu | E38: =INDEX(Articles!$B$2:$B$148,MATCH(C38,Articles!$A$2:$A$148,0)) -> Papex | F38: 2 | G38: =IF(INDEX(Articles!$G$2:$G$148,MATCH(C38,Articles!$A$2:$A$148,0))="","",INDEX(Articles!$G$2:$G$148,MATCH(C38,Articles!$A$2:$A$148,0))) -> 100 | H38: =IF(G38="",0,F38*G38) -> 200 | I38: =IF(INDEX(Articles!$E$2:$E$148,MATCH(C38,Articles!$A$2:$A$148,0))="","",INDEX(Articles!$E$2:$E$148,MATCH(C38,Articles!$A$2:$A$148,0))) | J38: =IF(I38="","",F38*I38) | K38: =INDEX(Articles!$H$2:$H$148,MATCH(C38,Articles!$A$2:$A$148,0)) -> Fixé | L38: =INDEX(Articles!$F$2:$F$148,MATCH(C38,Articles!$A$2:$A$148,0)) -> Inconnu | N38: Oui
A39: Art & dessin | B39: Paquet de crayons de couleur | C39: SAC-024 | D39: =INDEX(Articles!$C$2:$C$148,MATCH(C39,Articles!$A$2:$A$148,0)) -> Crayons de couleur Maped Nightfall, boîte de 24 | E39: =INDEX(Articles!$B$2:$B$148,MATCH(C39,Articles!$A$2:$A$148,0)) -> Papex | F39: 1 | G39: =IF(INDEX(Articles!$G$2:$G$148,MATCH(C39,Articles!$A$2:$A$148,0))="","",INDEX(Articles!$G$2:$G$148,MATCH(C39,Articles!$A$2:$A$148,0))) -> 1600 | H39: =IF(G39="",0,F39*G39) -> 1600 | I39: =IF(INDEX(Articles!$E$2:$E$148,MATCH(C39,Articles!$A$2:$A$148,0))="","",INDEX(Articles!$E$2:$E$148,MATCH(C39,Articles!$A$2:$A$148,0))) -> 1300 | J39: =IF(I39="","",F39*I39) -> 1300 | K39: =INDEX(Articles!$H$2:$H$148,MATCH(C39,Articles!$A$2:$A$148,0)) -> Estimé | L39: =INDEX(Articles!$F$2:$F$148,MATCH(C39,Articles!$A$2:$A$148,0)) -> Estimé | N39: Oui
A40: Manuels au programme | B40: Didactikos Langue et communication | C40: DID-6913 | D40: =INDEX(Articles!$C$2:$C$148,MATCH(C40,Articles!$A$2:$A$148,0)) -> Langue et communication C.I. | E40: =INDEX(Articles!$B$2:$B$148,MATCH(C40,Articles!$A$2:$A$148,0)) -> LPD | F40: 1 | G40: =IF(INDEX(Articles!$G$2:$G$148,MATCH(C40,Articles!$A$2:$A$148,0))="","",INDEX(Articles!$G$2:$G$148,MATCH(C40,Articles!$A$2:$A$148,0))) -> 3890 | H40: =IF(G40="",0,F40*G40) -> 3890 | I40: =IF(INDEX(Articles!$E$2:$E$148,MATCH(C40,Articles!$A$2:$A$148,0))="","",INDEX(Articles!$E$2:$E$148,MATCH(C40,Articles!$A$2:$A$148,0))) -> 2890 | J40: =IF(I40="","",F40*I40) -> 2890 | K40: =INDEX(Articles!$H$2:$H$148,MATCH(C40,Articles!$A$2:$A$148,0)) -> Fixé | L40: =INDEX(Articles!$F$2:$F$148,MATCH(C40,Articles!$A$2:$A$148,0)) -> Estimé | M40: « Didactikos langue, maths, DDM : 1 » lu comme 1 manuel par matière | N40: Oui
A41: Manuels au programme | B41: Didactikos Mathématiques | C41: DID-6936 | D41: =INDEX(Articles!$C$2:$C$148,MATCH(C41,Articles!$A$2:$A$148,0)) -> Mathématiques C.I. | E41: =INDEX(Articles!$B$2:$B$148,MATCH(C41,Articles!$A$2:$A$148,0)) -> LPD | F41: 1 | G41: =IF(INDEX(Articles!$G$2:$G$148,MATCH(C41,Articles!$A$2:$A$148,0))="","",INDEX(Articles!$G$2:$G$148,MATCH(C41,Articles!$A$2:$A$148,0))) -> 3890 | H41: =IF(G41="",0,F41*G41) -> 3890 | I41: =IF(INDEX(Articles!$E$2:$E$148,MATCH(C41,Articles!$A$2:$A$148,0))="","",INDEX(Articles!$E$2:$E$148,MATCH(C41,Articles!$A$2:$A$148,0))) -> 2890 | J41: =IF(I41="","",F41*I41) -> 2890 | K41: =INDEX(Articles!$H$2:$H$148,MATCH(C41,Articles!$A$2:$A$148,0)) -> Fixé | L41: =INDEX(Articles!$F$2:$F$148,MATCH(C41,Articles!$A$2:$A$148,0)) -> Estimé | M41: « Didactikos langue, maths, DDM : 1 » lu comme 1 manuel par matière | N41: Oui
A42: Manuels au programme | B42: Didactikos Découverte du monde | C42: DID-6949 | D42: =INDEX(Articles!$C$2:$C$148,MATCH(C42,Articles!$A$2:$A$148,0)) -> Découverte du monde C.I. | E42: =INDEX(Articles!$B$2:$B$148,MATCH(C42,Articles!$A$2:$A$148,0)) -> LPD | F42: 1 | G42: =IF(INDEX(Articles!$G$2:$G$148,MATCH(C42,Articles!$A$2:$A$148,0))="","",INDEX(Articles!$G$2:$G$148,MATCH(C42,Articles!$A$2:$A$148,0))) -> 3890 | H42: =IF(G42="",0,F42*G42) -> 3890 | I42: =IF(INDEX(Articles!$E$2:$E$148,MATCH(C42,Articles!$A$2:$A$148,0))="","",INDEX(Articles!$E$2:$E$148,MATCH(C42,Articles!$A$2:$A$148,0))) -> 2890 | J42: =IF(I42="","",F42*I42) -> 2890 | K42: =INDEX(Articles!$H$2:$H$148,MATCH(C42,Articles!$A$2:$A$148,0)) -> Fixé | L42: =INDEX(Articles!$F$2:$F$148,MATCH(C42,Articles!$A$2:$A$148,0)) -> Estimé | M42: « Didactikos langue, maths, DDM : 1 » lu comme 1 manuel par matière | N42: Oui
D43: Lignes sans prix de vente (à fournir) | H43: =COUNTIF(G33:G42,"") -> 0
D44: Total vente du kit (FCFA) | H44: =SUM(H33:H42) -> 18995
...

Sheet CP
A1: Kit CP
A2: Liste réelle du Complexe Dar El-Hadith. Contrôle croisé avec la liste ISJA 2026-2027 (plus chargée, écoles privées).
A4: CP — Essentiel
A5: Groupe (app) | B5: Besoin (liste) | C5: ID | D5: Désignation | E5: Fournisseur | F5: Qté | G5: PV unit. (FCFA) | H5: Sous-total vente | I5: PA unit. (FCFA) | J5: Sous-total achat | K5: Statut vente | L5: Statut achat | M5: Remarque | N5: Coché par défaut
A6: Cahiers | B6: Cahier 96 pages | C6: SAC-048 | D6: =INDEX(Articles!$C$2:$C$148,MATCH(C6,Articles!$A$2:$A$148,0)) -> Cahier Calligraphe 96 pages 17x22 56 g seyès | E6: =INDEX(Articles!$B$2:$B$148,MATCH(C6,Articles!$A$2:$A$148,0)) -> Papex | F6: 2 | G6: =IF(INDEX(Articles!$G$2:$G$148,MATCH(C6,Articles!$A$2:$A$148,0))="","",INDEX(Articles!$G$2:$G$148,MATCH(C6,Articles!$A$2:$A$148,0))) -> 450 | H6: =IF(G6="",0,F6*G6) -> 900 | I6: =IF(INDEX(Articles!$E$2:$E$148,MATCH(C6,Articles!$A$2:$A$148,0))="","",INDEX(Articles!$E$2:$E$148,MATCH(C6,Articles!$A$2:$A$148,0))) -> 350 | J6: =IF(I6="","",F6*I6) -> 700 | K6: =INDEX(Articles!$H$2:$H$148,MATCH(C6,Articles!$A$2:$A$148,0)) -> Fixé | L6: =INDEX(Articles!$F$2:$F$148,MATCH(C6,Articles!$A$2:$A$148,0)) -> Confirmé | N6: Oui
A7: Ardoise | B7: Ardoise | C7: S086 | D7: =INDEX(Articles!$C$2:$C$148,MATCH(C7,Articles!$A$2:$A$148,0)) -> Ardoise scolaire | E7: =INDEX(Articles!$B$2:$B$148,MATCH(C7,Articles!$A$2:$A$148,0)) -> LPD | F7: 1 | G7: =IF(INDEX(Articles!$G$2:$G$148,MATCH(C7,Articles!$A$2:$A$148,0))="","",INDEX(Articles!$G$2:$G$148,MATCH(C7,Articles!$A$2:$A$148,0))) -> 900 | H7: =IF(G7="",0,F7*G7) -> 900 | I7: =IF(INDEX(Articles!$E$2:$E$148,MATCH(C7,Articles!$A$2:$A$148,0))="","",INDEX(Articles!$E$2:$E$148,MATCH(C7,Articles!$A$2:$A$148,0))) -> 600 | J7: =IF(I7="","",F7*I7) -> 600 | K7: =INDEX(Articles!$H$2:$H$148,MATCH(C7,Articles!$A$2:$A$148,0)) -> Fixé | L7: =INDEX(Articles!$F$2:$F$148,MATCH(C7,Articles!$A$2:$A$148,0)) -> Estimé | N7: Oui
A8: Géométrie | B8: Règle | C8: S011 | D8: =INDEX(Articles!$C$2:$C$148,MATCH(C8,Articles!$A$2:$A$148,0)) -> Règle plastique transparente 20 cm | E8: =INDEX(Articles!$B$2:$B$148,MATCH(C8,Articles!$A$2:$A$148,0)) -> LPD | F8: 1 | G8: =IF(INDEX(Articles!$G$2:$G$148,MATCH(C8,Articles!$A$2:$A$148,0))="","",INDEX(Articles!$G$2:$G$148,MATCH(C8,Articles!$A$2:$A$148,0))) -> 100 | H8: =IF(G8="",0,F8*G8) -> 100 | I8: =IF(INDEX(Articles!$E$2:$E$148,MATCH(C8,Articles!$A$2:$A$148,0))="","",INDEX(Articles!$E$2:$E$148,MATCH(C8,Articles!$A$2:$A$148,0))) | J8: =IF(I8="","",F8*I8) | K8: =INDEX(Articles!$H$2:$H$148,MATCH(C8,Articles!$A$2:$A$148,0)) -> Fixé | L8: =INDEX(Articles!$F$2:$F$148,MATCH(C8,Articles!$A$2:$A$148,0)) -> Inconnu | N8: Oui
A9: Géométrie | B9: Matériel géométrique | C9: SAC-007 | D9: =INDEX(Articles!$C$2:$C$148,MATCH(C9,Articles!$A$2:$A$148,0)) -> Kit de traçage 30 cm, 4 pièces L'écolier | E9: =INDEX(Articles!$B$2:$B$148,MATCH(C9,Articles!$A$2:$A$148,0)) -> Papex | F9: 1 | G9: =IF(INDEX(Articles!$G$2:$G$148,MATCH(C9,Articles!$A$2:$A$148,0))="","",INDEX(Articles!$G$2:$G$148,MATCH(C9,Articles!$A$2:$A$148,0))) -> 900 | H9: =IF(G9="",0,F9*G9) -> 900 | I9: =IF(INDEX(Articles!$E$2:$E$148,MATCH(C9,Articles!$A$2:$A$148,0))="","",INDEX(Articles!$E$2:$E$148,MATCH(C9,Articles!$A$2:$A$148,0))) -> 650 | J9: =IF(I9="","",F9*I9) -> 650 | K9: =INDEX(Articles!$H$2:$H$148,MATCH(C9,Articles!$A$2:$A$148,0)) -> Estimé | L9: =INDEX(Articles!$F$2:$F$148,MATCH(C9,Articles!$A$2:$A$148,0)) -> Confirmé | N9: Oui
A10: Écriture | B10: Bic bleu | C10: SAC-065 | D10: =INDEX(Articles!$C$2:$C$148,MATCH(C10,Articles!$A$2:$A$148,0)) -> Stylo à bille Schneider Tops 505 M bleu | E10: =INDEX(Articles!$B$2:$B$148,MATCH(C10,Articles!$A$2:$A$148,0)) -> Papex | F10: 2 | G10: =IF(INDEX(Articles!$G$2:$G$148,MATCH(C10,Articles!$A$2:$A$148,0))="","",INDEX(Articles!$G$2:$G$148,MATCH(C10,Articles!$A$2:$A$148,0))) -> 100 | H10: =IF(G10="",0,F10*G10) -> 200 | I10: =IF(INDEX(Articles!$E$2:$E$148,MATCH(C10,Articles!$A$2:$A$148,0))="","",INDEX(Articles!$E$2:$E$148,MATCH(C10,Articles!$A$2:$A$148,0))) | J10: =IF(I10="","",F10*I10) | K10: =INDEX(Articles!$H$2:$H$148,MATCH(C10,Articles!$A$2:$A$148,0)) -> Fixé | L10: =INDEX(Articles!$F$2:$F$148,MATCH(C10,Articles!$A$2:$A$148,0)) -> Inconnu | N10: Oui
A11: Écriture | B11: Bic vert | C11: SAC-104 | D11: =INDEX(Articles!$C$2:$C$148,MATCH(C11,Articles!$A$2:$A$148,0)) -> Stylo à bille Schneider Tops 505 M vert | E11: =INDEX(Articles!$B$2:$B$148,MATCH(C11,Articles!$A$2:$A$148,0)) -> Papex | F11: 1 | G11: =IF(INDEX(Articles!$G$2:$G$148,MATCH(C11,Articles!$A$2:$A$148,0))="","",INDEX(Articles!$G$2:$G$148,MATCH(C11,Articles!$A$2:$A$148,0))) -> 100 | H11: =IF(G11="",0,F11*G11) -> 100 | I11: =IF(INDEX(Articles!$E$2:$E$148,MATCH(C11,Articles!$A$2:$A$148,0))="","",INDEX(Articles!$E$2:$E$148,MATCH(C11,Articles!$A$2:$A$148,0))) | J11: =IF(I11="","",F11*I11) | K11: =INDEX(Articles!$H$2:$H$148,MATCH(C11,Articles!$A$2:$A$148,0)) -> Fixé | L11: =INDEX(Articles!$F$2:$F$148,MATCH(C11,Articles!$A$2:$A$148,0)) -> Inconnu | N11: Oui
A12: Art & dessin | B12: Paquet de crayons de couleur | C12: SAC-019 | D12: =INDEX(Articles!$C$2:$C$148,MATCH(C12,Articles!$A$2:$A$148,0)) -> Crayons de couleur Maped, boîte de 12 | E12: =INDEX(Articles!$B$2:$B$148,MATCH(C12,Articles!$A$2:$A$148,0)) -> Papex | F12: 1 | G12: =IF(INDEX(Articles!$G$2:$G$148,MATCH(C12,Articles!$A$2:$A$148,0))="","",INDEX(Articles!$G$2:$G$148,MATCH(C12,Articles!$A$2:$A$148,0))) -> 900 | H12: =IF(G12="",0,F12*G12) -> 900 | I12: =IF(INDEX(Articles!$E$2:$E$148,MATCH(C12,Articles!$A$2:$A$148,0))="","",INDEX(Articles!$E$2:$E$148,MATCH(C12,Articles!$A$2:$A$148,0))) -> 650 | J12: =IF(I12="","",F12*I12) -> 650 | K12: =INDEX(Articles!$H$2:$H$148,MATCH(C12,Articles!$A$2:$A$148,0)) -> Estimé | L12: =INDEX(Articles!$F$2:$F$148,MATCH(C12,Articles!$A$2:$A$148,0)) -> Estimé | N12: Oui
D13: Lignes sans prix de vente (à fournir) | H13: =COUNTIF(G6:G12,"") -> 0
D14: Total vente du kit (FCFA) | H14: =SUM(H6:H12) -> 4000
D15: Coût de revient connu (FCFA) | H15: =SUM(J6:J12) -> 2600
D16: Lignes sans prix d'achat | H16: =COUNTIF(I6:I12,"") -> 3
D17: Marge sur les lignes au coût connu (FCFA) | H17: =SUMPRODUCT((I6:I12<>"")*H6:H12)-H15 -> 1000
D18: Nombre de cahiers (ligne « X cahiers » dans l'app) | H18: =SUMIF(A6:A12,"Cahiers",F6:F12) -> 2
D19: Part du prix de vente reposant sur des PV estimés | H19: =IF(H14=0,0,SUMIF(K6:K12,"<>Fixé",H6:H12)/H14) -> 0.45
D20: Statut du coût | H20: =IF(H13>0,"Total incomplet : "&H13&" prix de vente à fournir",IF(H16>0,"Coût incomplet : "&H16&" ligne(s) sans prix d'achat","Complet")) -> Coût incomplet : 3 ligne(s) sans prix d'achat
D22: Proposés décochés : livres du Complet (non comptés, cochables par le client)
A23: Manuels au programme | B23: Didactikos Langue et communication | C23: DID-6915 | D23: =INDEX(Articles!$C$2:$C$148,MATCH(C23,Articles!$A$2:$A$148,0)) -> Langue et communication C.P. | G23: =INDEX(Articles!$G$2:$G$148,MATCH(C23,Articles!$A$2:$A$148,0)) -> 3890 | N23: Non
A24: Manuels au programme | B24: Didactikos Mathématiques | C24: DID-6938 | D24: =INDEX(Articles!$C$2:$C$148,MATCH(C24,Articles!$A$2:$A$148,0)) -> Mathématiques C.P. | G24: =INDEX(Articles!$G$2:$G$148,MATCH(C24,Articles!$A$2:$A$148,0)) -> 3890 | N24: Non
A25: Manuels au programme | B25: Didactikos Découverte du monde | C25: DID-6952 | D25: =INDEX(Articles!$C$2:$C$148,MATCH(C25,Articles!$A$2:$A$148,0)) -> Découverte du monde C.P. | G25: =INDEX(Articles!$G$2:$G$148,MATCH(C25,Articles!$A$2:$A$148,0)) -> 3890 | N25: Non
D26: Total si tous les livres sont cochés (FCFA) | H26: =H14+SUM(G23:G25) -> 15670
D27: Option décochée par défaut, non comptée : | E27: =INDEX(Articles!$C$2:$C$148,MATCH("S027",Articles!$A$2:$A$148,0)) -> Cartable rigide bleu marine | H27: =INDEX(Articles!$G$2:$G$148,MATCH("S027",Articles!$A$2:$A$148,0)) -> 7500
D28: Manquants : | E28: aucun
A31: CP — Complet
A32: Groupe (app) | B32: Besoin (liste) | C32: ID | D32: Désignation | E32: Fournisseur | F32: Qté | G32: PV unit. (FCFA) | H32: Sous-total vente | I32: PA unit. (FCFA) | J32: Sous-total achat | K32: Statut vente | L32: Statut achat | M32: Remarque | N32: Coché par défaut
A33: Cahiers | B33: Cahier 96 pages | C33: SAC-033 | D33: =INDEX(Articles!$C$2:$C$148,MATCH(C33,Articles!$A$2:$A$148,0)) -> Cahier Calligraphe 140 pages 17x22 90 g seyès | E33: =INDEX(Articles!$B$2:$B$148,MATCH(C33,Articles!$A$2:$A$148,0)) -> Papex | F33: 2 | G33: =IF(INDEX(Articles!$G$2:$G$148,MATCH(C33,Articles!$A$2:$A$148,0))="","",INDEX(Articles!$G$2:$G$148,MATCH(C33,Articles!$A$2:$A$148,0))) -> 750 | H33: =IF(G33="",0,F33*G33) -> 1500 | I33: =IF(INDEX(Articles!$E$2:$E$148,MATCH(C33,Articles!$A$2:$A$148,0))="","",INDEX(Articles!$E$2:$E$148,MATCH(C33,Articles!$A$2:$A$148,0))) -> 650 | J33: =IF(I33="","",F33*I33) -> 1300 | K33: =INDEX(Articles!$H$2:$H$148,MATCH(C33,Articles!$A$2:$A$148,0)) -> Fixé | L33: =INDEX(Articles!$F$2:$F$148,MATCH(C33,Articles!$A$2:$A$148,0)) -> Estimé | M33: 140 p Calligraphe 90 g | N33: Oui
A34: Ardoise | B34: Ardoise | C34: CIS-ardoise | D34: =INDEX(Articles!$C$2:$C$148,MATCH(C34,Articles!$A$2:$A$148,0)) -> Ardoise quadrillée avec poignée | E34: =INDEX(Articles!$B$2:$B$148,MATCH(C34,Articles!$A$2:$A$148,0)) -> Cissé & Frères | F34: 1 | G34: =IF(INDEX(Articles!$G$2:$G$148,MATCH(C34,Articles!$A$2:$A$148,0))="","",INDEX(Articles!$G$2:$G$148,MATCH(C34,Articles!$A$2:$A$148,0))) -> 2500 | H34: =IF(G34="",0,F34*G34) -> 2500 | I34: =IF(INDEX(Articles!$E$2:$E$148,MATCH(C34,Articles!$A$2:$A$148,0))="","",INDEX(Articles!$E$2:$E$148,MATCH(C34,Articles!$A$2:$A$148,0))) -> 1500 | J34: =IF(I34="","",F34*I34) -> 1500 | K34: =INDEX(Articles!$H$2:$H$148,MATCH(C34,Articles!$A$2:$A$148,0)) -> Fixé | L34: =INDEX(Articles!$F$2:$F$148,MATCH(C34,Articles!$A$2:$A$148,0)) -> Confirmé | N34: Oui
A35: Géométrie | B35: Règle | C35: S069 | D35: =INDEX(Articles!$C$2:$C$148,MATCH(C35,Articles!$A$2:$A$148,0)) -> Règle métal 30 cm | E35: =INDEX(Articles!$B$2:$B$148,MATCH(C35,Articles!$A$2:$A$148,0)) -> LPD | F35: 1 | G35: =IF(INDEX(Articles!$G$2:$G$148,MATCH(C35,Articles!$A$2:$A$148,0))="","",INDEX(Articles!$G$2:$G$148,MATCH(C35,Articles!$A$2:$A$148,0))) -> 550 | H35: =IF(G35="",0,F35*G35) -> 550 | I35: =IF(INDEX(Articles!$E$2:$E$148,MATCH(C35,Articles!$A$2:$A$148,0))="","",INDEX(Articles!$E$2:$E$148,MATCH(C35,Articles!$A$2:$A$148,0))) -> 400 | J35: =IF(I35="","",F35*I35) -> 400 | K35: =INDEX(Articles!$H$2:$H$148,MATCH(C35,Articles!$A$2:$A$148,0)) -> Fixé | L35: =INDEX(Articles!$F$2:$F$148,MATCH(C35,Articles!$A$2:$A$148,0)) -> Estimé | N35: Oui
